Workbook

Sheet Main
A1: Entertainment Universe
A2: number in mio USD
A3: # | B3: Name | C3: TCKR | D3: Country | E3: Price | F3: MC | G3: Net Debt | H3: EV | I3: Updated | J3: Nxt Upd. | S3: Notes
A4: 1 | B4: Netflix | C4: NFLX | D4: US | E4: =+[1]Main!$I$3 -> 97.5 | F4: =+[1]Main!$I$5 -> 411660.81 | G4: =+[1]Main!$I$7-[1]Main!$I$6 -> 5400.477 | H4: =+F4+G4 -> 417061.29 | I4: Q425 | S4: Streaming Serivce
A5: =+A4+1 -> 2 | B5: Disney Company | C5: DIS | D5: US | E5: =+[2]Main!$K$2 -> 115.68 | F5: =+[2]Main!$K$4 -> 207984.99 | G5: =+[2]Main!$K$6-[2]Main!$K$5 -> 31164 | H5: =+F5+G5 -> 239148.99 | I5: Q325 | J5: 45966 | S5: Media, Streaming, Parks
A6: =+A5+1 -> 3 | B6: Comcast | C6: CMCSA | D6: US | E6: =+[3]Main!$I$2 -> 29.6 | F6: =+[3]Main!$I$4 -> 107859.28 | G6: =+[3]Main!$I$6-[3]Main!$I$5 -> 89738 | H6: =+F6+G6 -> 197597.28 | I6: Q225 | S6: Media, Streaming, Parks
A7: =+A6+1 -> 4 | B7: Sony | C7: SONY | D7: JAP | E7: =+[4]Main!$H$2 -> 3214 | F7: =+[4]Main!$H$4*FX!C2 -> 124966.16 | G7: =+([4]Main!$H$6-[4]Main!$H$5)*FX!C2 -> 12550.618 | H7: =+F7+G7 -> 137516.78 | I7: FQ224 | S7: Consumer Electronics
A8: =+A7+1 -> 5 | B8: Spotify | C8: SPOT | D8: SWE | E8: =+[5]Main!$H$2 -> 627.5 | F8: =+[5]Main!$H$5*FX!C3 -> 132772.61 | G8: =+([5]Main!$H$7-[5]Main!$H$6)*FX!C3 -> -8594.32 | H8: =+F8+G8 -> 124178.29 | I8: Q225 | S8: Streaming Serivce
A9: =+A8+1 -> 6 | B9: Nintedno | C9: 7974.T | D9: JAP | E9: =+[6]Main!$I$2 -> 12800 | F9: =+[6]Main!$I$4*FX!C2 -> 106388.68 | G9: =+([6]Main!$I$6-[6]Main!$I$5)*FX!C2 -> -10152.16 | H9: =+F9+G9 -> 96236.525 | I9: FQ224 | S9: Consumer Electronics
A10: =+A9+1 -> 7 | B10: Sea (Garena) | C10: SE | D10: SING | E10: =+[7]Main!$I$2 -> 141.63 | F10: =+[7]Main!$I$4 -> 82151.98 | G10: =+[7]Main!$I$6-[7]Main!$I$5 -> 1013.508 | H10: =+F10+G10 -> 83165.488 | I10: Q424
A11: =+A10+1 -> 8 | B11: NetEase | C11: NTES | D11: CHI
A12: =+A11+1 -> 9 | B12: Universal Music | C12: UMG.AS | D12: NE
A13: =+A12+1 -> 10 | B13: Flutter Entertainment | C13: FLUT | D13: IRE
A14: =+A13+1 -> 11 | B14: Naspers | C14: NPSNY | D14: SA
A15: =+A14+1 -> 12 | B15: Electronic Arts | C15: EA | D15: US | E15: =+[8]Main!$I$2 -> 202.53 | F15: =+[8]Main!$I$4 -> 50674.485 | G15: =+[8]Main!$I$6-[8]Main!$I$5 -> -1230 | H15: =+F15+G15 -> 49444.485 | I15: FQ126 | J15: 45958 | S15: Game Developer
A16: =+A15+1 -> 13 | B16: Roblox | C16: RBLX | D16: US | E16: =+[9]Main!$H$2 -> 127.88 | F16: =+[9]Main!$H$4 -> 82486.819 | G16: =+[9]Main!$H$6-[9]Main!$H$5 -> -1634.819 | H16: =+F16+G16 -> 80852 | I16: Q225 | S16: Game Developer
A17: =+A16+1 -> 14 | B17: Las Vegas Sands | C17: LVS | D17: US | E17: =+[10]Main!$G$2 -> 51.15 | F17: =+[10]Main!$G$4 -> 37085.089 | G17: =+[10]Main!$G$6-[10]Main!$G$5 -> 9804 | H17: =+F17+G17 -> 46889.089 | I17: Q324 | S17: Gambling
A18: =+A17+1 -> 15 | B18: Pop Mart | C18: 9992.HK | D18: CHI | E18: =+[11]Main!$I$2 -> 266.8 | F18: =+[11]Main!$I$4*FX!C6 -> 49644.394 | G18: =+([11]Main!$I$6-[11]Main!$I$5)*FX!C6 -> -1927.1995 | H18: =+F18+G18 -> 47717.194 | I18: Q225
A19: =+A18+1 -> 16 | B19: Oriental Land | C19: 4661.T | D19: JAP
A20: =+A19+1 -> 17 | B20: Take 2 Interactive | C20: TTWO | D20: US | E20: =+[12]Main!$L$3 -> 228.01 | F20: =+[12]Main!$L$5 -> 42061.053 | G20: =+[12]Main!$L$7-[12]Main!$L$6 -> 1030 | H20: =+F20+G20 -> 43091.053 | I20: FQ126 | S20: Game Developer
A21: =+A20+1 -> 18 | B21: Live Nation | C21: LYV | D21: US | E21: =+[13]Main!$H$2 -> 134.9 | F21: =+[13]Main!$H$4 -> 31344.512 | G21: =+[13]Main!$H$6-[13]Main!$H$5 -> 764.973 | H21: =+F21+G21 -> 32109.485 | I21: Q324 | S21: Tickets
A22: =+A21+1 -> 19 | B22: Aristocat | C22: ALL.AX | D22: AUS | E22: =+[14]Main!$I$2 -> 66.67 | F22: =+[14]Main!$I$4*FX!C5 -> 26732.303 | G22: =+([14]Main!$I$6-[14]Main!$I$5)*FX!C5 -> 718.452 | H22: =+F22+G22 -> 27450.755 | I22: Q424 | S22: Online Casino
A23: =+A22+1 -> 20 | B23: Warner Bros | C23: WBD | D23: US | E23: =+[15]Main!$H$2 -> 25.88 | F23: =+[15]Main!$H$4 -> 64072.987 | G23: =+[15]Main!$H$6-[15]Main!$H$5 -> 29744 | H23: =+F23+G23 -> 93816.987 | I23: Q225 | J23: 45967 | S23: Production
A24: =+A23+1 -> 21 | B24: Formula One Group | C24: FWONK | D24: US | E24: =+[16]Main!$G$3 -> 95 | F24: =+[16]Main!$G$5 -> 23679.881 | G24: =+[16]Main!$G$7-[16]Main!$G$6 -> 1592 | H24: =+F24+G24 -> 25271.881 | I24: Q424 | S24: Media, Sports
A25: =+A24+1 -> 22 | B25: Tencent Music | C25: TME | D25: CHI
A26: =+A25+1 -> 23 | B26: DraftKings | C26: DKNG | D26: US | E26: =+[17]Main!$G$2 -> 45.96 | F26: =+[17]Main!$G$4 -> 22817.764 | G26: =+[17]Main!$G$6-[17]Main!$G$5 -> -669.265 | H26: =+F26+G26 -> 22148.499 | I26: Q225 | S26: Gambling
A27: =+A26+1 -> 24 | B27: Warner Music Group | C27: WMG | D27: US | E27: =+[18]Main!$H$2 -> 33.81 | F27: =+[18]Main!$H$4 -> 17624.033 | G27: =+[18]Main!$H$6-[18]Main!$H$5 -> 3836 | H27: =+F27+G27 -> 21460.033 | I27: FQ125 | S27: Music Label
A28: =+A27+1 -> 25 | B28: Evolution Gaming | C28: EVO.ST | D28: SWE
A29: =+A28+1 -> 26 | B29: Bandai Namco | C29: 7832.T | D29: JAP | E29: =+[19]Main!$I$2 -> 5241 | F29: =+[19]Main!$I$4*FX!C2 -> 21944.564 | G29: =+([19]Main!$I$6-[19]Main!$I$5)*FX!C2 -> -2059.9552 | H29: =+F29+G29 -> 19884.609
A30: =+A29+1 -> 27 | B30: Konami Holdings | C30: 9766.T | D30: JAP | E30: =+[20]Main!$I$2 -> 16735 | F30: =+[20]Main!$I$4*FX!C2 -> 14518.75 | G30: =+([20]Main!$I$6-[20]Main!$I$5)*FX!C2 -> -1445.152 | H30: =+F30+G30 -> 13073.598 | I30: FQ325
A31: =+A30+1 -> 28 | B31: Nexon | C31: 3659.T | D31: JAP
A32: =+A31+1 -> 29 | B32: TKO Group | C32: TKO | D32: US | E32: =+[21]Main!$J$2 -> 184.82 | F32: =+[21]Main!$J$4 -> 15180.539 | G32: =+[21]Main!$J$6-[21]Main!$J$5 -> 2214.253 | H32: =+F32+G32 -> 17394.792 | I32: Q225
A33: =+A32+1 -> 30 | B33: MGM Resorts | C33: MGM | D33: US
A34: =+A33+1 -> 31 | B34: Churchill Downs | C34: CHDN | D34: US
A35: =+A34+1 -> 32 | B35: Endeavour Group | C35: DER | D35: US
A36: =+A35+1 -> 33 | B36: Wynn Resorts | C36: WYNN | D36: US
A37: =+A36+1 -> 34 | B37: International Games | C37: 3293.T | D37: TWN
A38: =+A37+1 -> 35 | B38: CTS Eventim | C38: EVD.F | D38: GER
A39: =+A38+1 -> 36 | B39: Hasbro | C39: HAS | D39: US | E39: =+[22]Main!$H$2 -> 65.32 | F39: =+[22]Main!$H$4 -> 9114.1865 | G39: =+[22]Main!$H$6-[22]Main!$H$5 -> 2685.8 | H39: =+F39+G39 -> 11799.987 | I39: Q424 | S39: Games/Board Games
A40: =+A39+1 -> 37 | B40: Light&Wonder | C40: LNW | D40: US
...

Sheet Gaming
A1: Main
A2: numbers in mio USD
A3: # | B3: Name | C3: Tickr | D3: Country | E3: Price | F3: MarketCap | G3: Net Debt | H3: EV | I3: Update
B4: Game Developers
A5: 1 | B5: Microsoft | C5: MSFT | D5: US | E5: =+[32]Main!$H$2 -> 432.32 | F5: =+[32]Main!$H$4 -> 3210248 | G5: =+[32]Main!$H$6-[32]Main!$H$5 -> -49200 | H5: =+F5+G5 -> 3161048 | I5: FQ225
A6: =+A5+1 -> 2 | B6: Tencent | C6: TECHY | D6: CHI | E6: =+[33]Main!$G$2 -> 617.5 | F6: =+[33]Main!$G$4*FX!C6 -> 1273.58 | G6: =+([33]Main!$G$6-[33]Main!$G$5)*FX!C6 -> -674313.6 | H6: =+F6+G6 -> -673040.02 | I6: Q324
A7: =+A6+1 -> 3 | B7: Sony | C7: SONY | D7: JAP | E7: =+[4]Main!$H$2 -> 3214 | F7: =+[4]Main!$H$4*FX!C2 -> 124966.16 | G7: =+([4]Main!$H$6-[4]Main!$H$5)*FX!C2 -> 12550.618 | H7: =+F7+G7 -> 137516.78 | I7: FQ224
A8: =+A7+1 -> 4 | B8: Nintendo | C8: 7974T | D8: JAP | E8: =+[6]Main!$I$2 -> 12800 | F8: =+[6]Main!$I$4*FX!C2 -> 106388.68 | G8: =+([6]Main!$I$6-[6]Main!$I$5)*FX!C2 -> -10152.16 | H8: =+F8+G8 -> 96236.525 | I8: FQ324
A9: =+A8+1 -> 5 | B9: Net Ease | C9: NTES | D9: CHI | E9: =+[34]Main!$I$2 -> 2123 | F9: =+[35]Main!$H$5*FX!C6 -> 65131.275 | G9: =+([35]Main!$H$7-[35]Main!$H$6)*FX!C6 -> -16042.826 | H9: =+F9+G9 -> 49088.449 | I9: Q424
A10: =+A9+1 -> 6 | B10: Sea (Garena) | C10: SE | D10: SING | E10: =+[7]Main!$I$2 -> 141.63 | F10: =+[7]Main!$I$4 -> 82151.98 | G10: =+[7]Main!$I$6-[7]Main!$I$5 -> 1013.508 | H10: =+F10+G10 -> 83165.488 | I10: Q424
A11: =+A10+1 -> 7 | B11: Electronic Arts | C11: EA | D11: US | E11: =+[8]Main!$I$2 -> 202.53 | F11: =+[8]Main!$I$4 -> 50674.485 | G11: =+[8]Main!$I$6-[8]Main!$I$5 -> -1230 | H11: =+F11+G11 -> 49444.485 | I11: FQ225
A12: =+A11+1 -> 8 | B12: Take Two | C12: TTWO | D12: US | E12: =+[12]Main!$L$3 -> 228.01 | F12: =+[12]Main!$L$5 -> 42061.053 | G12: =+[12]Main!$L$7-[12]Main!$L$6 -> 1030 | H12: =+F12+G12 -> 43091.053 | I12: FQ225
A13: =+A12+1 -> 9 | B13: Roblox | C13: RBLX | D13: US | E13: =+[9]Main!$H$2 -> 127.88 | F13: =+[9]Main!$H$4 -> 82486.819 | G13: =+[9]Main!$H$6-[9]Main!$H$5 -> -1634.819 | H13: =+F13+G13 -> 80852 | I13: Q224
A14: =+A13+1 -> 10 | B14: Aristocrat | C14: ALL.AX | D14: AUS | E14: =+[14]Main!$I$2 -> 66.67 | F14: =+[14]Main!$I$4*FX!C5 -> 26732.303 | G14: =+([14]Main!$I$6-[14]Main!$I$5)*FX!C5 -> 718.452 | H14: =+F14+G14 -> 27450.755 | I14: Q424
A15: =+A14+1 -> 11 | B15: Nexon | C15: 3659.T | D15: JAP | E15: =+[34]Main!$I$2 -> 2123 | F15: =+[34]Main!$I$4*FX!C2 -> 11429.017 | G15: =+([34]Main!$I$6-[34]Main!$I$5)*FX!C2 -> -2117.3888 | H15: =+F15+G15 -> 9311.6278 | I15: Q424
A16: =+A15+1 -> 12 | B16: Bandai Namco | C16: 7832.T | D16: JAP | E16: =+[19]Main!$I$2 -> 5241 | F16: =+[19]Main!$I$4*FX!C2 -> 21944.564 | G16: =+([19]Main!$I$6-[19]Main!$I$5)*FX!C2 -> -2059.9552 | H16: =+F16+G16 -> 19884.609 | I16: Q325
A17: =+A16+1 -> 13 | B17: Konami Holdings | C17: 9766.T | D17: JAP | E17: =+[20]Main!$I$2 -> 16735 | F17: =+[20]Main!$I$4*FX!C2 -> 14518.75 | G17: =+([20]Main!$I$6-[20]Main!$I$5)*FX!C2 -> -1445.152 | H17: =+F17+G17 -> 13073.598 | I17: Q325
A18: =+A17+1 -> 14 | B18: Ubisoft | C18: UBI.PA | D18: FRA | E18: =+[36]Main!$H$2 -> 12.11 | F18: =+[36]Main!$H$4*FX!C3 -> 1601.5717 | G18: =+([36]Main!$H$6-[36]Main!$H$5)*FX!C3 -> 1343.738 | H18: =+F18+G18 -> 2945.3097 | I18: Q424
B20: Distributors
B21: Gamestop | C21: GME | D21: US | E21: =+[37]Main!$J$2 -> 21.7 | F21: =+[37]Main!$J$4 -> 9701.7224 | G21: =+[37]Main!$J$6-[37]Main!$J$5 -> -4758 | H21: =+F21+G21 -> 4943.7224 | I21: Q424

Sheet Media
A1: Main
A2: numbers in mio USD
A3: # | B3: Name | C3: Ticker | D3: Country | E3: Price | F3: MC | G3: Net Debt | H3: EV | I3: Updated
A4: 1 | B4: Comcast | C4: CMCSA | D4: US | E4: =+[3]Main!$I$2 -> 29.6 | F4: =+[3]Main!$I$4 -> 107859.28 | G4: =+[3]Main!$I$6-[3]Main!$I$5 -> 89738 | H4: =+F4+G4 -> 197597.28 | I4: Q325
A5: =+A4+1 -> 2 | B5: Thomson Reuters | C5: TRI | D5: CA
A6: =+A5+1 -> 3 | B6: Naspers | C6: NPSNY | D6: SAF
A7: =+A6+1 -> 4 | B7: Warner Bros Disc. | C7: WBD | D7: US | E7: =+[15]Main!$H$2 -> 25.88 | F7: =+[15]Main!$H$4 -> 64072.987 | G7: =+[15]Main!$H$6-[15]Main!$H$5 -> 29744 | H7: =+F7+G7 -> 93816.987 | I7: Q324
A8: =+A7+1 -> 5 | B8: Fox Corp | C8: FOX | D8: US | E8: =+[38]Main!$I$2 -> 50.5 | F8: =+[38]Main!$I$4 -> 22898.107 | G8: =+[38]Main!$I$6-[38]Main!$I$5 -> 3878 | H8: =+F8+G8 -> 26776.107 | I8: FQ225
A9: =+A8+1 -> 6 | B9: BCE | C9: BCE | D9: CA
A10: =+A9+1 -> 7 | B10: Rogers Com. | C10: RCI | D10: CA
A11: =+A10+1 -> 8 | B11: News Corp | C11: NWS | D11: US | E11: =+[39]Main!$I$2 -> 30.44 | F11: =+[39]Main!$I$4 -> 17310.539 | G11: =+[39]Main!$I$6-[39]Main!$I$5 -> 1122 | H11: =+F11+G11 -> 18432.539 | I11: Q324
A12: =+A11+1 -> 9 | B12: Endevaor Group | C12: EDR | D12: US
A13: =+A12+1 -> 10 | B13: Trump Media | C13: DJT | D13: US | E13: =+[40]Main!$H$2 -> 41.21 | F13: =+[40]Main!$H$4 -> 8939.4565 | G13: =+[40]Main!$H$6-[40]Main!$H$5 -> -663.4447 | H13: =+F13+G13 -> 8276.0118 | I13: Q324
A14: =+A13+1 -> 11 | B14: New York Times | C14: NYT | D14: US | E14: =+[41]Main!$H$2 -> 69.87 | F14: =+[41]Main!$H$4 -> 11343.325 | G14: =+[41]Main!$H$6-[41]Main!$H$5 -> -617.352 | H14: =+F14+G14 -> 10725.973 | I14: Q325
A15: =+A14+1 -> 12 | B15: Paramount | C15: PARA | D15: US | E15: =+[23]Main!$I$2 -> 13.8 | F15: =+[23]Main!$I$4 -> 9315 | G15: =+[23]Main!$I$6-[23]Main!$I$5 -> 11775 | H15: =+F15+G15 -> 21090 | I15: Q424
A16: =+A15+1 -> 13 | B16: Schibsted | C16: SCHA.OL | D16: NOR
A17: =+A16+1 -> 14 | B17: Liberty Live | C17: LLYVA | D17: US | E17: =+[42]Main!$K$2 -> 78.55 | F17: =+[42]Main!$K$4 -> 7215.2326 | G17: =+[42]Main!$K$6-[42]Main!$K$5 -> 1417 | H17: =+F17+G17 -> 8632.2326 | I17: Q125
A18: =+A17+1 -> 15 | B18: Saudi R&M Group | C18: 4210.SR | D18: SR
A19: =+A18+1 -> 16 | B19: Quebecor | C19: QBR-B.TO | D19: CA
A20: =+A19+1 -> 17 | B20: MBC Group | C20: 4072.SR | D20: SA
A21: =+A20+1 -> 18 | B21: Nexstar Media | C21: NXST | D21: US
A22: =+A21+1 -> 19 | B22: RTL | C22: RTL.F | D22: LU
A23: =+A22+1 -> 20 | B23: Nippon Television | C23: 9404.T | D23: JAP
A24: =+A23+1 -> 21 | B24: Millicom | C24: TIGO | D24: LU
A25: =+A24+1 -> 22 | B25: Graham Holdings | C25: GHC | D25: US
A26: =+A25+1 -> 23 | B26: IAC | C26: IAC | D26: US
A27: =+A26+1 -> 24 | B27: Travel+Leisure | C27: TNL | D27: US
A28: =+A27+1 -> 25 | B28: ITV plc | C28: ITV.L | D28: UK
A29: =+A28+1 -> 26 | B29: Peloton | C29: PTON | D29: US
... A34: =+A33+1 -> 31 | B34: MultiChoice | C34: MCG.JO | D34: SAF
A35: =+A34+1 -> 32 | B35: John Wiley
A36: =+A35+1 -> 33 | B36: Ziff Davis | C36: ZD | D36: US
A37: =+A36+1 -> 34 | B37: TX Group | C37: TXGN.SW | D37: SW
A38: =+A37+1 -> 35 | B38: Cogeco | C38: CCA.TO | D38: CA
A39: =+A38+1 -> 36 | B39: MFE | C39: MFE.MI | D39: ITA
A40: =+A39+1 -> 37 | B40: Elang Mahkota | C40: EMTK.JK | D40: IND
A41: =+A40+1 -> 38 | B41: NOS | C41: NOS.LS | D41: POR
A42: =+A41+1 -> 39 | B42: TF1 | C42: TFI.PA | D42: FR
A43: =+A42+1 -> 40 | B43: Groupe M6 | C43: MMT.PA | D43: FR
A44: =+A43+1 -> 41 | B44: fuboTV | C44: FUBO | D44: US
...

Sheet FX
B2: YEN/USD | C2: 0.0064
B3: EUR/USD | C3: 1.03
B4: GBP/USD | C4: 1.24
B5: AUD/USD | C5: 0.63
B6: RMB/USD | C6: 0.14
