Workbook

Sheet Main
A1: Fashion Universe
A2: in mio USD
A3: # | B3: Name | C3: TCKR | D3: Country | E3: Price | F3: MC | G3: Net Debt | H3: EV | I3: Updated | J3: Nxt Rslts | K3: Rev LFY | L3: RG | M3: EBIT | N3: NI | O3: GM | P3: EBIT-M. | Q3: A. P/E | R3: F. P/E | S3: A. PEG | T3: F. PEG | U3: P/B | V3: EV/Sales | W3: EV/EBITDA | X3: Beta | Y3: ROE | Z3: ROCE | AA3: ROIC | AB3: Stores | AC3: Employees | AD3: Founded | AE3: Descripition | AH3: Notes
A4: x | B4: Total Industry | C4: =+COUNTA(C6:C183) -> 178 | D4: =+COUNTA(_xlfn.UNIQUE(D6:D183)) -> 32 | E4: / | F4: =SUM(F6:F156) -> 1834524.3 | G4: =SUM(G6:G156) -> -8675.0034 | H4: =SUM(H6:H156) -> 1825849.3 | I4: Q425 | J4: / | K4: =SUM(K6:K156) -> 492429.91 | L4: =SUMPRODUCT(L6:L183,K6:K183)/SUM(K6:K1820) -> 0.039002441 | M4: =SUM(M6:M87) -> 86102.332 | N4: =SUM(N6:N87) -> 51484.743
A5: x | B5: Industry Average | C5: / | D5: {=_xlfn.LET(_xlpm.rng,D6:D183,INDEX(_xlpm.rng,MATCH(MAX(COUNTIF(_xlpm.rng,_xlpm.rng)),COUNTIF(_xlpm.rng,_xlpm.rng),0)))} -> US | E5: / | F5: =+AVERAGE(F6:F183) -> 22653.501 | G5: =AVERAGE(G6:G156) -> -108.43754 | H5: =AVERAGE(H6:H156) -> 22823.117 | I5: Q425 | J5: / | K5: =AVERAGE(K6:K156) -> 25917.364 | L5: =AVERAGE(L6:L183) -> 0.058894737 | M5: =AVERAGE(M6:M87) -> 4783.4629 | N5: =AVERAGE(N6:N87) -> 3028.5143 | O5: =AVERAGE(O6:O87) -> 0.54647059 | P5: =AVERAGE(P6:P87) -> 0.16238105 | Q5: =AVERAGE(Q6:Q87) -> 29.227273 | R5: =AVERAGE(R6:R87) -> 30.644444 | S5: =AVERAGE(S6:S87) -> 1.1667143 | T5: =AVERAGE(T6:T87) -> -1.1 | ... AA5: =AVERAGE(AA6:AA87) -> 0.19857143
A6: 1 | B6: LVMH | C6: MC.PA | D6: FRA | E6: =+[1]Main!$I$4 -> 459.1 | F6: =+[1]Main!$I$6*FX!C3 -> 236731.94 | G6: =(+[1]Main!$I$8-[1]Main!$I$7)*FX!C3 -> 14229.28 | H6: =F6+G6 -> 250961.22 | I6: Q226 | J6: 46308 | K6: =80807*FX!C3 -> 84039.28 | L6: -0.05 | M6: =18907*FX!C3 -> 19663.28 | N6: =12550*FX!C3 -> 13052 | O6: 0.67 | P6: =+M6/K6 -> 0.23397725 | Q6: 25.7 | R6: 23.3 | S6: 1.752 | T6: -11.97 | U6: 3.4 | V6: 3.1 | W6: 13.73 | Y6: 0.18 | Z6: 0.13 | AA6: 0.14 | AB6: 6307 | AC6: 213618 | AD6: 1987 | AE6: Leather Goods, Luxury/Appereal
A7: =+A6+1 -> 2 | B7: Hermes | C7: RMS | D7: FRA | E7: =+[2]Main!$K$2 -> 1553 | F7: =+[2]Main!$K$4*FX!C3 -> 169253.66 | G7: =+([2]Main!$K$6-[2]Main!$K$5)*FX!C3 -> -12797.2 | H7: =F7+G7 -> 156456.46 | I7: Q226 | J7: 46318 | K7: =16002*FX!C3 -> 16642.08 | L7: 0.05 | M7: =5650*1.08 -> 6102 | N7: =4311*1.08 -> 4655.88 | O7: 0.7 | P7: 0.37 | Q7: 55.2 | R7: 46.9 | S7: =155.7/100 -> 1.557 | T7: 2.4 | U7: 11.1 | V7: 13.1 | W7: 32.2 | X7: 0.74 | Y7: 0.26 | Z7: 0.5 | AA7: 0.33 | AC7: 23242 | AD7: 1837 | AE7: Leather Goods, Luxury/Appereal
A8: =+A7+1 -> 3 | B8: Inditex | C8: ITX.MC | D8: SPA | E8: =+[3]Main!$J$3 -> 54.85 | F8: =+[3]Main!$J$5*FX!C3 -> 177744.63 | G8: =+([3]Main!$J$7-[3]Main!$J$6)*FX!C3 -> -10813.92 | H8: =F8+G8 -> 166930.71 | I8: Q226 | J8: 46358 | K8: =35947*FX!C3 -> 37384.88 | L8: 0.1 | M8: =6808*FX!C3 -> 7080.32 | N8: =5394*FX!C3 -> 5609.76 | O8: 0.58 | P8: 0.19 | Q8: 22.6 | R8: 21.4 | S8: 1.7 | T8: 3.9 | U8: 7.3 | V8: 3.3 | W8: 12.81 | Y8: 0.24 | Z8: 0.4 | AA8: 0.32 | AB8: 5695 | AD8: 1985 | AE8: Fast Fashion
A9: =+A8+1 -> 4 | B9: TJX Companies | C9: TJX | D9: US | E9: =+[4]Main!$I$3 -> 141.19 | F9: =+[4]Main!$I$5 -> 157709.23 | G9: =+[4]Main!$I$7-[4]Main!$I$6 -> -3133 | H9: =F9+G9 -> 154576.23 | I9: FQ227 | J9: 46344 | K9: 54217 | L9: 0.09 | M9: 5797 | N9: 4474 | O9: 0.29 | P9: 0.11 | Q9: 32.1 | R9: 29.4 | S9: 2 | U9: 17.4 | V9: 2.6 | W9: 17 | Y9: 0.57 | Z9: 0.29 | AA9: 0.29 | AB9: 4952 | AD9: 1987 | AE9: Retailer
A10: =+A9+1 -> 5 | B10: Dior | C10: CDI.PA | D10: FRA | E10: =+[5]Main!$I$2 -> 471.6 | F10: =+[5]Main!$I$4*FX!C3 -> 88484.895 | G10: =+([5]Main!$I$6-[5]Main!$I$5)*FX!C3 -> 13724.88 | H10: =F10+G10 -> 102209.77 | I10: Q424 | J10: n.a. | K10: 86153 | L10: 0.09 | M10: 22796 | N10: 6304 | O10: 0.68 | P10: 0.27 | AD10: 1945 | AE10: Leather Goods, Luxury/Appereal
A11: =+A10+1 -> 6 | B11: Nike | C11: NKE | D11: US | E11: =+[6]Main!$I$3 -> 44.05 | F11: =+[6]Main!$I$5 -> 65348.118 | G11: =+[6]Main!$I$7-[6]Main!$I$6 -> -1085 | H11: =F11+G11 -> 64263.118 | I11: FQ426 | J11: 46294 | K11: 51362 | L11: 0 | M11: 6311 | N11: 6097 | O11: 0.45 | P11: 0.12 | Q11: 34.9 | R11: 40.8 | S11: 0.57 | T11: 1.27 | U11: 7.2 | V11: 1.9 | W11: 25.2 | Y11: 0.37 | Z11: 0.24 | AA11: 0.14 | AB11: 1045 | AD11: 1964 | AE11: Athletic Footwear, Appereal
A12: =+A11+1 -> 7 | B12: Fast Retailing | C12: 9983.T | D12: JAP | E12: =+[7]Main!$J$3 -> 82110 | F12: =+[7]Main!$J$5*FX!C5 -> 158723.66 | G12: =+([7]Main!$J$7-[7]Main!$J$6)*FX!C5 -> 1460.2324 | H12: =F12+G12 -> 160183.89 | I12: FQ326 | J12: 46303 | K12: =2301122*FX!C5 -> 14497.069 | L12: 0.08 | M12: =+SUM([7]Model!$G$20:$I$20,[7]Model!$C$20)*FX!C5 -> 3765.132 | N12: =433010*FX!C5 -> 2727.963 | O12: 0.55 | P12: 0.18 | Q12: 36.8 | R12: 35.6 | U12: 6.9 | V12: 4.4 | AB12: 1512 | AD12: 1949 | AE12: Fast Fashion
A13: =+A12+1 -> 8 | B13: Cintas | C13: CTAS | D13: US | E13: =+[8]Main!$K$2 -> 205.28 | F13: =+[8]Main!$K$4 -> 82146.807 | G13: =+[8]Main!$K$6-[8]Main!$K$5 -> 2139.055 | H13: =F13+G13 -> 84285.862 | I13: FQ426 | J13: 46288 | K13: 8815.8 | L13: 0.12 | M13: 1807.2 | N13: 1348 | O13: 0.47 | P13: 0.2 | Q13: 41.7 | R13: 39.5 | AD13: 1929 | AE13: Uniform/Work Clothing
A14: =+A13+1 -> 9 | B14: Ross Stores | C14: ROST | D14: US | E14: =+[9]Main!$H$3 -> 249.68 | F14: =+[9]Main!$H$5 -> 79320.09 | G14: =+[9]Main!$H$7-[9]Main!$H$6 -> -3269.612 | H14: =F14+G14 -> 76050.478 | I14: Q227 | J14: 46345 | K14: 20376.9 | L14: 0.09 | M14: 2307.7 | N14: 1874.5 | O14: 0.28 | P14: 0.12 | AD14: 1982 | AE14: Discounter
A15: =+A14+1 -> 10 | B15: LuluLemon | C15: LULU | D15: CAN | E15: =+[10]Main!$I$2 -> 99.65 | F15: =+[10]Main!$I$4 -> 10522.448 | G15: =+[10]Main!$I$6-[10]Main!$I$5 -> -189.737 | H15: =F15+G15 -> 10332.711 | I15: Q126 | J15: 46366 | K15: 9619.3 | L15: 0.19 | M15: 2132.7 | N15: 1550.2 | O15: 0.58 | P15: 0.2 | AD15: 1998 | AE15: Athletic Appereal, Footwear
A16: =+A15+1 -> 11 | B16: Adidas | C16: ADS | D16: GER | E16: =+[11]Main!$I$2 -> 159.1 | F16: =+[11]Main!$I$4*FX!C3 -> 29166.594 | G16: =+([11]Main!$I$6-[11]Main!$I$5)*FX!C3 -> 1965.6 | H16: =F16+G16 -> 31132.194 | I16: Q126 | J16: 46324 | K16: =21427*FX!C3 -> 22284.08 | L16: -0.05 | M16: =267*FX!C3 -> 277.68 | N16: =-77*FX!C3 -> -80.08 | O16: 0.5 | P16: 0.06 | AD16: 1949 | AE16: Athletic Footwear, Appereal
A17: =+A16+1 -> 12 | B17: Coupang | C17: CPNG | D17: KOR | E17: =+[86]Main!$I$2 -> 22.51 | F17: =+[86]Main!$I$4 -> 40518 | G17: =+[86]Main!$I$6-[86]Main!$I$5 -> -4497 | H17: =+F17+G17 -> 36021 | I17: Q425
A18: =+A17+1 -> 13 | B18: Kering | C18: KER.PA | D18: FRA | E18: =+[12]Main!$H$2 -> 250.5 | F18: =+[12]Main!$H$4*FX!C3 -> 31944.883 | G18: =+([12]Main!$H$6-[12]Main!$H$5)*FX!C3 -> 3456.96 | H18: =F18+G18 -> 35401.843 | I18: Q226 | J18: 46316 | K18: =17194*FX!C3 -> 17881.76 | L18: -0.12 | M18: =2313*FX!C3 -> 2405.52 | N18: =1133*FX!C3 -> 1178.32 | O18: 0.74 | P18: 0.15 | Q18: 16.7 | S18: 0.7 | U18: 5.3 | V18: 4 | W18: 7.67 | X18: 0.87 | Y18: 0.08 | Z18: 0.08 | AA18: 0.07 | AB18: 1794 | AC18: 46930 | AD18: 1962 | AE18: Leather Goods, Luxury/Appereal
A19: =+A18+1 -> 14 | B19: Anta Sport Products | C19: 2020.HK | D19: CH | E19: =+[13]Main!$H$2 -> 78.75 | F19: =+[13]Main!$H$5*FX!C9 -> 28408.68 | G19: =+([13]Main!$H$7-[13]Main!$H$6)*FX!C9 -> -2787.26 | H19: =F19+G19 -> 25621.42 | I19: Q226 | K19: =70826*FX!C9 -> 9915.64 | L19: 0.14 | M19: =16595*FX!C9 -> 2323.3 | Q19: 19.5 | R19: 19.5 | U19: 3.2 | V19: 3 | AD19: 1991 | AE19: Athletic Appereal, Footwear
A20: =+A19+1 -> 15 | B20: Deckers Outdor | C20: DECK | D20: US | E20: =+[14]Main!$M$2 -> 103.91 | F20: =+[14]Main!$M$4 -> 14174.802 | G20: =+[14]Main!$M$6-[14]Main!$M$5 -> -1602.589 | H20: =F20+G20 -> 12572.213 | I20: Q127 | J20: 46317 | K20: 4985.612 | L20: 0.16 | M20: 1179.1 | N20: 967.2 | O20: 0.58 | P20: =+M20/K20 -> 0.23650055 | Q20: 19 | R20: 19.4 | U20: 7.2 | V20: 3.3 | AD20: 1973 | AE20: Athletic/Outdoor Shoes
A21: =+A20+1 -> 16 | B21: Tapestry | C21: TPR | D21: US | E21: =+[15]Main!$J$2 -> 130 | F21: =+[15]Main!$J$4 -> 25920.918 | G21: =+[15]Main!$J$6-[15]Main!$J$5 -> 1227 | H21: =F21+G21 -> 27147.918 | I21: FQ426 | J21: 46331 | AD21: 2000 | AE21: Leather Goods, Appereal
A22: =+A21+1 -> 17 | B22: H&M | C22: HM-B.ST | D22: SWE | E22: =+[16]Main!$I$2 -> 166.25 | F22: =+[16]Main!$I$4*FX!C4 -> 25232.111 | G22: =+([16]Main!$I$6-[16]Main!$I$5)*FX!C4 -> 187.91 | H22: =F22+G22 -> 25420.021 | I22: Q226 | J22: 46289 | K22: =234478*FX!C4 -> 22275.41 | L22: -0.01 | AD22: 1947 | AE22: Fast Fashion
A23: =+A22+1 -> 18 | B23: Ralph Lauren Corp | C23: RL | D23: US | E23: =+[17]Main!$H$2 -> 389.9 | F23: =+[17]Main!$H$4 -> 23231.115 | G23: =+[17]Main!$H$6-[17]Main!$H$5 -> -633.5 | H23: =F23+G23 -> 22597.615 | I23: Q127 | J23: 46331 | K23: 6631.4 | L23: 0.029 | M23: 756.4 | N23: 646.3 | O23: 0.64 | P23: 0.11 | Q23: 17.3 | S23: =-11.2/100 -> -0.112 | U23: 3.52 | V23: 1.51 | W23: 10.3 | X23: 0.75 | Y23: 0.21 | Z23: 0.14 | AA23: 0.1 | AD23: 1967 | AE23: Appereal and other
A24: =+A23+1 -> 19 | B24: Asics Corp | C24: 7936.T | D24: JAP | E24: =+[18]Main!$I$2 -> 5281 | F24: =+[18]Main!$I$4*FX!C5 -> 23581.79 | G24: =+([18]Main!$I$6-[18]Main!$I$5)*FX!C5 -> -471.0321 | H24: =F24+G24 -> 23110.758 | I24: Q226 | J24: 46337 | AD24: 1949 | AE24: Athletic Appereal, Footwear
A25: =+A24+1 -> 20 | B25: Shein | C25: 0625.HK | D25: CH | E25: =+[80]Main!$J$2 -> 48.5 | F25: =+[80]Main!$J$5 -> 26772.307 | G25: =+[80]Main!$J$7-[80]Main!$J$6 -> -15210 | H25: =+F25+G25 -> 11562.307 | I25: Q226
A26: =+A25+1 -> 21 | B26: Prada | C26: 1913.HK | D26: ITA | E26: =+[19]Main!$H$2 -> 43.26 | F26: =+[19]Main!$H$5*FX!C3 -> 13814.702 | G26: =(+[19]Main!$H$7-[19]Main!$H$6)*FX!C3 -> 727.22728 | H26: =F26+G26 -> 14541.929 | I26: Q226 | J26: 46317 | AD26: 1913 | AE26: Leather Goods, Luxury/Appereal
A27: =+A26+1 -> 22 | B27: Trent Ltd | C27: TRENT.NS | D27: IND | E27: =+[20]Main!$I$2 -> 2992.7 | F27: =+[20]Main!$I$4*FX!C12 -> 11702.541 | G27: =+([20]Main!$I$6-[20]Main!$I$5)*FX!C12 -> 2616.768 | H27: =+F27+G27 -> 14319.309 | I27: Q426
A28: =+A27+1 -> 23 | B28: Moncler | C28: MONC.MI | D28: ITA | E28: =+[21]Main!$H$2 -> 47.32 | F28: =+[21]Main!$H$4*FX!C3 -> 13313.188 | G28: =+([21]Main!$H$6-[21]Main!$H$5)*FX!C3 -> -376.31984 | H28: =F28+G28 -> 12936.868 | I28: Q226 | J28: 46316 | AD28: 1952 | AE28: Luxury Appereal
A29: =+A28+1 -> 24 | B29: Burlington Store | C29: BURL | D29: US | E29: =+[22]Main!$I$2 -> 294.94 | F29: =+[22]Main!$I$4 -> 18845.486 | G29: =+[22]Main!$I$6-[22]Main!$I$5 -> 1189.825 | H29: =F29+G29 -> 20035.311 | I29: Q226 | J29: 46350 | AD29: 1972 | AE29: Retailer
A30: =+A29+1 -> 25 | B30: Next plc | C30: NXT.L | D30: UK | E30: =+[23]Main!$I$2 -> 156 | F30: =+[23]Main!$I$4*FX!C8 -> 22613.136 | G30: =+([23]Main!$I$6-[23]Main!$I$5)*FX!C8 -> 883.748 | H30: =F30+G30 -> 23496.884 | I30: Q425 | J30: 46282 | AD30: 1864 | AE30: Retailer
A31: =+A30+1 -> 26 | B31: On Holding Ag | C31: ONON | D31: SWI | E31: =+[24]Main!$H$2 -> 30.85 | F31: =+[24]Main!$H$5*FX!C7 -> 8718.9329 | G31: =+([24]Main!$H$7-[24]Main!$H$6)*FX!C7 -> -1077.888 | H31: =F31+G31 -> 7641.0449 | I31: Q226 | J31: 46337 | AD31: 2010 | AE31: Athletic Footwear, Appereal
A32: =+A31+1 -> 27 | B32: Amer Sports | C32: AS | D32: FIN | E32: =+[25]Main!$J$2 -> 33.79 | F32: =+[25]Main!$J$4 -> 19685.281 | G32: =+[25]Main!$J$6-[25]Main!$J$5 -> -573 | H32: =F32+G32 -> 19112.281 | I32: Q226 | J32: 46343 | AD32: 1950 | AE32: Sports Goods
A33: =+A32+1 -> 28 | B33: Shenzou International | C33: 2313.HK | D33: CH | E33: =+[26]Main!$J$2 -> 35.46 | F33: =+[26]Main!$J$5*FX!C9 -> 6567.0856 | G33: =+([26]Main!$J$7-[26]Main!$J$6)*FX!C9 -> -3721.6155 | H33: =F33+G33 -> 2845.4701 | I33: Q226 | J33: 46441 | AD33: 1991 | AE33: Appereal and other
A34: =+A33+1 -> 29 | B34: Huali Industrial | C34: 300979.SZ | D34: CH | E34: =+[27]Main!$K$2 -> 76.74 | F34: =+[27]Main!$K$4*FX!C9 -> 12537.781 | G34: =+([27]Main!$K$6-[27]Main!$K$5)*FX!C9 -> -745.22328 | H34: =+G34+F34 -> 11792.558 | I34: Q423 | J34: n.a | AD34: 2004 | AE34: Shoe Manufacturer
A35: =+A34+1 -> 30 | B35: Zalando | C35: ZAL.DE | D35: GER | E35: =+[28]Main!$I$2 -> 25.27 | F35: =+[28]Main!$I$4*FX!C3 -> 6543.9192 | G35: =+([28]Main!$I$6-[28]Main!$I$5)*FX!C3 -> -477.152 | H35: =F35+G35 -> 6066.7672 | I35: Q226 | J35: 46329 | AD35: 2008 | AE35: Online Retailer
A36: =+A35+1 -> 31 | B36: VF Corporation | C36: VFC | D36: US | E36: =+[29]Main!$H$2 -> 14.5 | F36: =+[29]Main!$H$4 -> 5700.4513 | G36: =+[29]Main!$H$6-[29]Main!$H$5 -> 2343.042 | H36: =+G36+F36 -> 8043.4933 | I36: FQ127 | J36: 46322 | AD36: 1899 | AE36: Work Appereal
A37: =+A36+1 -> 32 | B37: Birkenstock Holding | C37: BIRK | D37: GER | E37: =+[30]Main!$I$3 -> 34.85 | F37: =+[30]Main!$I$5*FX!C3 -> 6665.4911 | G37: =+([30]Main!$I$7-[30]Main!$I$6)*FX!C3 -> 1033.526 | H37: =F37+G37 -> 7699.0171 | I37: Q326 | J37: 46373 | AD37: 1774 | AE37: Sandals
A38: =+A37+1 -> 33 | B38: GAP Inc | C38: GAP | D38: US | E38: =+[31]Main!$J$2 -> 23.84 | F38: =+[31]Main!$J$4 -> 8463.2 | G38: =+([31]Main!$J$6-[31]Main!$J$5) -> -992 | H38: =+G38+F38 -> 7471.2 | I38: Q226 | J38: 46345 | K38: 14889 | L38: 0.05 | M38: 560 | N38: 502 | O38: 0.37 | P38: 0.04 | AD38: 1969 | AE38: Appereal and other
A39: =+A38+1 -> 34 | B39: Skechers Inc | C39: SKX | D39: US | E39: =+[32]Main!$I$2 -> 60.4 | F39: =+[32]Main!$I$4 -> 9118.7086 | G39: =+[32]Main!$I$6-[32]Main!$I$5 -> -838.962 | H39: =F39+G39 -> 8279.7466 | I39: Q324 | J39: Acquired | AD39: 1992 | AE39: Footwear
A40: =+A39+1 -> 35 | B40: Brunello Cucinelli | C40: BC.MI | D40: ITA | E40: =+[33]Main!$J$2 -> 87.92 | F40: =+[33]Main!$J$4*FX!C3 -> 6217.1242 | G40: =+([33]Main!$J$6-[33]Main!$J$5)*FX!C3 -> 227.71216 | H40: =F40+G40 -> 6444.8363 | I40: Q226 | J40: 46310 | AD40: 1978 | AE40: Luxury Appereal
...

Sheet Sports
A1: Main
A3: # | B3: Name | C3: TCKR | D3: Country | E3: Price | F3: MC | G3: Net Debt | H3: EV | I3: Updated | J3: Nxt Rslts | K3: Rev LFY | L3: RG | M3: EBIT LFY | N3: NI LFY | O3: GM | P3: EBIT-M. | Q3: A. P/E | R3: F. P/E | S3: A. PEG | T3: F. PEG | U3: P/B | V3: EV/Sales | W3: EV/EBITDA | X3: Beta | Y3: ROE | Z3: ROCE | AA3: ROIC | AB3: Stores | AC3: Employees | AD3: Founded | AE3: Descripition | AH3: Notes
A4: 1 | B4: Nike | C4: NKE | D4: US
A5: =+A4+1 -> 2 | B5: Adidas | C5: ADS | D5: GER
A6: =+A5+1 -> 3 | B6: Lululemon | C6: LULU | D6: CA
A7: =+A6+1 -> 4 | B7: Anta Sports | C7: 2020.HK | D7: CH
A8: =+A7+1 -> 5 | B8: Deckers Outdoor | C8: DECK | D8: US
A9: =+A8+1 -> 6 | B9: Asics Corp | C9: 7936.T | D9: JAP
A10: =+A9+1 -> 7 | B10: On Holding | C10: ONON | D10: SW
A11: =+A10+1 -> 8 | B11: Amer Sports | C11: AS | D11: FIN
A12: =+A11+1 -> 9 | B12: Skechers | C12: SKX | D12: US
A13: =+A12+1 -> 10 | B13: Gildan Activewear | C13: GIL | D13: CA
A14: =+A13+1 -> 11 | B14: JD Sports Fashion | C14: JD.L | D14: UK
A15: =+A14+1 -> 12 | B15: Li Ning Corp | C15: 2331.HK | D15: CH
A16: =+A15+1 -> 13 | B16: Puma | C16: PUM.DE | D16: GER
... A18: =+A17+1 -> 15 | B18: Geox | C18: GEOX | D18: US
A19: =+A18+1 -> 16 | B19: Wolverine Worldwide | C19: WWW | D19: US | E19: =+[79]Main!$J$2 -> 19.99 | F19: =+[79]Main!$J$4 -> 1640.5061 | G19: =+[79]Main!$J$6-[79]Main!$J$5 -> 388.6 | H19: =+F19+G19 -> 2029.1061 | I19: Q226
A20: =+A19+1 -> 17 | B20: Dicks Sporting Goods | C20: DKS | D20: US | E20: =+[81]Main!$J$2 -> 127.52 | F20: =+[81]Main!$J$4 -> 11289.983 | G20: =+[81]Main!$J$6-[81]Main!$J$5 -> 992.612 | H20: =+F20+G20 -> 12282.595 | I20: Q226 | J20: 46350
A21: =+A20+1 -> 18 | B21: Mizuno Corp | C21: 8022.T | D21: JAP
A22: =+A21+1 -> 19 | B22: Shimano | C22: 7309.T | D22: JAP
A23: =+A22+1 -> 20 | B23: Footlocker | C23: FL | D23: US | E23: Acquired by Dicks Sporting Goods for 2.4 billion USD
A24: =+A23+1 -> 21 | B24: Planet Fitness | C24: PLNT | D24: US
A25: =+A24+1 -> 22 | B25: Acushnet Holdings | C25: GOLF | D25: US
A26: =+A25+1 -> 23 | B26: Columbia Spotswear | C26: COLM | D26: US
A27: =+A26+1 -> 24 | B27: Academy Sports | C27: ASO | D27: US
A28: =+A27+1 -> 25 | B28: Technogym | C28: TGYM.MI | D28: ITA
A29: =+A28+1 -> 26 | B29: Topsports International | C29: 6110.HK | D29: HK
A30: =+A29+1 -> 27 | B30: Peloton | C30: PTON | D30: US
A31: =+A30+1 -> 28 | B31: Topgolg Callaway Brands | C31: MODG | D31: US
A32: =+A31+1 -> 29 | B32: Escalade Sports | C32: ESCA | D32: US
A33: =+A32+1 -> 30 | B33: XXL ASA | C33: XXL.OL | D33: NOR
A34: =+A33+1 -> 31 | B34: Sportsman Warehouse | C34: SPWH | D34: US
A35: =+A34+1 -> 32 | B35: Big 5 Sporting Goods | C35: BGFV | D35: US
A36: =+A35+1 -> 33 | B36: Connexa Sports Technologies | C36: YYAI | D36: US
A37: =+A36+1 -> 34
A38: =+A37+1 -> 35
A39: =+A38+1 -> 36

Sheet Retail
A1: Main
A2: numbers in mio USD
A3: # | B3: Name | C3: TCKR | D3: Country | E3: Price | F3: MC | G3: Net Debt | H3: EV | I3: Updated | J3: Nxt Rslts | K3: Rev LFY | L3: RG | M3: EBIT LFY | N3: NI LFY | O3: GM | P3: EBIT-M. | Q3: A. P/E | R3: F. P/E | S3: A. PEG | T3: F. PEG | U3: P/B | V3: EV/Sales | W3: EV/EBITDA | X3: Beta | Y3: ROE | Z3: ROCE | AA3: ROIC | AB3: Stores | AC3: Employees | AD3: Founded | AE3: Descripition | AH3: Notes
A4: 1 | B4: TJX Companies | C4: TJX | D4: US | E4: 124.5 | F4: 141681 | G4: -2469 | H4: 139212 | I4: Q425 | J4: 45798 | K4: 54217 | L4: 0.09 | M4: 5797 | N4: 4474 | O4: 0.29 | P4: 0.11 | Q4: 24 | S4: 2 | U4: 14 | V4: 2 | W4: 17 | Y4: 0.57 | Z4: 0.29 | AA4: 0.29 | AB4: 4952 | AD4: 1987 | AE4: Retailer
A5: =+A4+1 -> 2 | B5: Burlington Store | C5: BURL | D5: US | E5: 292.68 | F5: 18579.62 | G5: 855.735 | H5: 19435.355 | I5: Q224 | J5: 45723 | AD5: 1972 | AE5: Retailer
A6: =+A5+1 -> 3 | B6: Next plc | C6: NXT.L | D6: UK | E6: 101.55 | F6: 15871.713 | G6: 880.276 | H6: 16751.989 | I6: Q224 | J6: 45736 | AD6: 1864 | AE6: Retailer
A7: =+A6+1 -> 4 | B7: Zalando | C7: ZAL.DE | D7: GER | E7: 32.3 | F7: 8703.6872 | G7: -912.08 | H7: 7791.6072 | I7: Q125 | AD7: 2008 | AE7: Online Retailer
A8: =+A7+1 -> 5 | B8: Pepkor | C8: PPH.JO | D8: SA | E8: 27.8 | F8: 5512.4064 | G8: 392.364 | H8: 5904.7704 | I8: Q424 | J8: 45804 | AD8: 1956 | AE8: Retailer
A9: =+A8+1 -> 6 | B9: Nordstrom | C9: JWN | D9: US | E9: 24.29 | F9: 4005.5895 | G9: 2220 | H9: 6225.5895 | AE9: Retailer
A10: =+A9+1 -> 7 | B10: Victoria Secret | C10: VSCO | D10: US | E10: 34.99 | F10: 2750.9694 | G10: 1257 | H10: 4007.9694 | I10: Q324 | J10: 45722 | AD10: 1977 | AE10: Retailer
A11: =+A10+1 -> 8 | B11: Revolve | C11: RVLV | D11: US | E11: 24.73 | F11: 1761.5194 | G11: -256.6 | H11: 1504.9194 | I11: Q424 | AD11: 2003 | AE11: Retailer

Sheet Accessoires
A1: Main
A2: numbers in mio USD
A3: x | B3: Name | C3: Ticker | D3: Country | E3: Price | F3: MC | G3: Net Debt | H3: EV | I3: Updated | J3: Next
A4: 1 | B4: Essilor Luxottica | C4: EL.PA | D4: FRA | E4: =+[82]Main!$I$2 -> 165.3 | F4: =+[82]Main!$I$4*FX!C3 -> 78910.853 | G4: =+([82]Main!$I$6-[82]Main!$I$5)*FX!C3 -> 9857.12 | H4: =+F4+G4 -> 88767.973 | I4: Q226 | J4: 46315
A5: =+A4+1 -> 2 | B5: Richemont | C5: CFR.SW | D5: SW | E5: =+[83]Main!$J$2 -> 157.35 | F5: =+[83]Main!$J$5*FX!C7 -> 109823.2 | G5: =+([83]Main!$J$7-[83]Main!$J$6)*FX!C7 -> 243.04 | H5: =+F5+G5 -> 110066.24 | I5: FQ127 | J5: 46339
A6: =+A7+1 -> 4 | B6: Estee Lauder | C6: EL | D6: US | E6: =+[84]Main!$K$2 -> 80.58 | F6: =+[84]Main!$K$4 -> 29153.434 | G6: =+([84]Main!$K$6-[84]Main!$K$5) -> 4186 | H6: =+F6+G6 -> 33339.434 | I6: Q326
A7: =+A5+1 -> 3 | B7: Swatch Group | C7: UHR.SW | D7: SW | E7: =+[85]Main!$I$3 -> 177.95 | F7: =+[85]Main!$I$5*FX!C7 -> 10344.706 | G7: =+([85]Main!$I$7-[85]Main!$I$6)*FX!C7 -> -1336.16 | H7: =+F7+G7 -> 9008.5459 | I7: Q425 | J7: 46099
A8: =+A6+1 -> 5 | B8: Titan Company | C8: TITAN.NS | D8: IND
A9: =+A8+1 -> 6 | B9: Pandora | C9: PNDRA | D9: DEN
A10: =+A9+1 -> 7 | B10: Chow Tai Fook | C10: 1929.HK | D10: CH
A11: =+A10+1 -> 8 | B11: Coty | C11: COTY | D11: US
A12: =+A11+1 -> 9 | B12: Kaylan Jewellers India | C12: KALYANKJIL.NS | D12: IND
A13: =+A12+1 -> 10 | B13: Nordstrom | C13: JWN | D13: US
A14: =+A13+1 -> 11 | B14: Signet Jewelers | C14: SIG | D14: BER
A15: =+A14+1 -> 12 | B15: Lovisa Holdings | C15: LOV.AX | D15: AX
A16: =+A15+1 -> 13 | B16: Phu Nhuan Jewelery | C16: PNJ.VN | D16: VN
A17: =+A16+1 -> 14 | B17: Salvatore Ferregamo | C17: SFER.MI | D17: ITA
A18: =+A17+1 -> 15 | B18: Mytherese | C18: MYTE | D18: GER
A19: =+A18+1 -> 16 | B19: Ethos Wathces | C19: ETHOSLTD.NS | D19: IND
A20: =+A19+1 -> 17 | B20: Rajesh Exports | C20: RAJESHEXPO.NS | D20: IND
... A29: =+A28+1 -> 26 | B29: Lanvin Group | C29: LANV | D29: CH
A30: =+A29+1 -> 27 | B30: Tods | C30: TODGF
A31: =+A30+1 -> 28 | B31: Hoya | C31: 7741.T | D31: JAP
A32: =+A31+1 -> 29 | B32: Cooper Companies | C32: COO | D32: US
A33: =+A32+1 -> 30 | B33: Fielmann | C33: FIE.F | D33: GER
A34: =+A33+1 -> 31 | B34: Bausch + Lomb | C34: BLCO | D34: CA
A35: =+A34+1 -> 32 | B35: Warby Paker | C35: WRBY | D35: US
A36: =+A35+1 -> 33 | B36: National Vision | C36: EYE | D36: US
A37: =+A36+1 -> 34 | B37: Synsam | C37: SYNSAM.ST | D37: SWE
A38: =+A37+1 -> 35 | B38: Menicon CO | C38: 7780.T | D38: JAP
A39: =+A38+1 -> 36 | B39: Safilo Group | C39: SFL.MI | D39: ITA
A40: =+A39+1 -> 37 | B40: Kits Eyecare | C40: KITS.TO | D40: CA
A41: =+A40+1 -> 38 | B41: Mister Spex | C41: MRX.F | D41: GER
A42: =+A41+1 -> 39 | B42: Innovative Eyewear | C42: LUCY | D42: US
... A54: =+A53+1 -> 51 | B54: Turpaz Industries | C54: TRPZ.TA | D54: IS

Sheet Luxury
A1: Main
A2: numbers in mio USD
A3: x | B3: Name | C3: Ticker | D3: Country | E3: Price | F3: MC | G3: Net Debt | H3: EV | I3: Updated | J3: Next | K3: Description
A4: 1 | B4: LVMH | C4: MC.PA | D4: FRA | K4: Leather Goods
A5: =+A4+1 -> 2 | B5: Hermes | C5: RMS.PA | D5: FRA | K5: Leather Goods
A6: =+A5+1 -> 3 | B6: Essillor Luxottica | C6: EL.PA | D6: FRA | K6: Eyewear
A7: =+A6+1 -> 4 | B7: Richemont | C7: CFR.SW | D7: SW | K7: Jewellery
A8: =+A7+1 -> 5 | B8: Dior | C8: CDI.PA | D8: FRA | K8: Leather Goods
A9: =+A8+1 -> 6 | B9: Titan Company | C9: TITAN.NS | D9: IND | K9: Jewellery
A10: =+A9+1 -> 7 | B10: Kering | C10: KER.PA | D10: FRA | K10: Leather Goods
A11: =+A10+1 -> 8 | B11: Moncler | C11: MONC.MI | D11: ITA | K11: Apperal
A12: =+A11+1 -> 9 | B12: Chow Tai Fook | C12: 1929.HK | D12: HK
A13: =+A12+1 -> 10 | B13: Prada | C13: 1913.HK | D13: ITA | K13: Apperal
A14: =+A13+1 -> 11 | B14: Brunello Cucinelli | C14: BC.MI | D14: ITA | K14: Apperal
A15: =+A14+1 -> 12 | B15: Pandora | C15: PNDORA.CO | D15: DEN
A16: =+A15+1 -> 13 | B16: Burberry | C16: BRBY.L | D16: UK | K16: Apperal
A17: =+A16+1 -> 14 | B17: Signet Juwellery | C17: SIG | D17: BER
A18: =+A17+1 -> 15 | B18: Ermeneglido Zegna | C18: ZGN | D18: ITA
A19: =+A18+1 -> 16 | B19: Coty | C19: COTY | D19: US | K19: Beauty
A20: =+A19+1 -> 17 | B20: Pattern Group | C20: PTRN | D20: US
A21: =+A20+1 -> 18 | B21: Lovisa Holdings | C21: LOV.AX | D21: AUS
A22: =+A21+1 -> 19 | B22: Watches of Switzerland | C22: WOSG.L | D22: UK
A23: =+A22+1 -> 20 | B23: Swatch Group | C23: UHR.SW | D23: SW
A24: =+A23+1 -> 21 | B24: Salvatore Ferragamo | C24: SFER.MI | D24: ITA
A25: =+A24+1 -> 22 | B25: Lanvin Group | C25: LANV | D25: HK
A26: =+A25+1 -> 23 | B26: Este Lauder | C26: EL | D26: US
A27: =+A26+1 -> 24
A28: =+A27+1 -> 25
A29: =+A28+1 -> 26
A30: =+A29+1 -> 27
A31: =+A30+1 -> 28
A32: =+A31+1 -> 29
A33: =+A32+1 -> 30
A34: =+A33+1 -> 31
A35: =+A34+1 -> 32
A36: =+A35+1 -> 33
A37: =+A36+1 -> 34
A38: =+A37+1 -> 35
... A51: =+A50+1 -> 48

Sheet Furniture
A1: Main
A2: numbers in mio USD
A3: x | B3: Name | C3: Ticker | D3: Country | E3: Price | F3: MC | G3: Net Debt | H3: EV | I3: Updated | J3: Next
A4: 1 | B4: Williams-Sonoma | C4: WSM | D4: US
A5: =+A4+1 -> 2 | B5: The AZEK Company | C5: AZEK | D5: US
A6: =+A5+1 -> 3 | B6: Wayfair | C6: W | D6: US
A7: =+A6+1 -> 4 | B7: Harvey Norman | C7: HVN.AX | D7: AX
A8: =+A7+1 -> 5 | B8: Restoration Hardware | C8: RH | D8: US
A9: =+A8+1 -> 6 | B9: HNI Corporation | C9: HNI | D9: US
A10: =+A9+1 -> 7 | B10: La-Z-Boy | C10: LZB | D10: US
A11: =+A10+1 -> 8 | B11: MasterBrand | C11: MBC | D11: US
A12: =+A11+1 -> 9 | B12: Rusta AB | C12: RUSTA.ST | D12: SWE
A13: =+A12+1 -> 10 | B13: Steelcase | C13: SCS | D13: US
A14: =+A13+1 -> 11 | B14: Arhaus | C14: ARHS | D14: US
A15: =+A14+1 -> 12 | B15: Leon's Furniture | C15: LNF.TO | D15: CA
A16: =+A15+1 -> 13 | B16: MillerKnoll | C16: MLKN | D16: US
... A21: =+A20+1 -> 18 | B21: RAK Ceramics | C21: RAKCEC.AE | D21: UAE
A22: =+A21+1 -> 19 | B22: Al-Saif Stores for Development &amp
A23: =+A22+1 -> 20 | B23: Itoki Corporation | C23: 7972.T | D23: JAP
A24: =+A23+1 -> 21 | B24: Kid ASA | C24: KID.OL | D24: NOR
A25: =+A24+1 -> 22 | B25: DFS Furniture | C25: DFS.L | D25: UK
A26: =+A25+1 -> 23 | B26: Roche Bobois | C26: RBO.PA | D26: FR
A27: =+A26+1 -> 24 | B27: Havertys | C27: HVT | D27: US
A28: =+A27+1 -> 25 | B28: home24 | C28: H24.HM | D28: GER
A29: =+A28+1 -> 26 | B29: LoveSac | C29: LOVE | D29: US
A30: =+A29+1 -> 27 | B30: Nobia AB | C30: NOBI.ST | D30: SWE
A31: =+A30+1 -> 28 | B31: Dexelance | C31: DEX.MI | D31: ITA
A32: =+A31+1 -> 29 | B32: Vista Alegre Atlantis | C32: VAF.LS | D32: POR
A33: =+A32+1 -> 30 | B33: Flexsteel Industries | C33: FLXS | D33: US
A34: =+A33+1 -> 31 | B34: Westwing Group | C34: WEW.DE | D34: GER
... A48: =+A47+1 -> 45 | B48: Conn's | C48: CONN | D48: US
A49: =+A48+1 -> 46

Sheet Shoes
A1: Main
B19: Private
B20: Zellerfeld

Sheet Glossar
B3: Haute couture | C3: (wörtlich: gehobene Schneiderkunst -> Maßgeschneiderte Mode, die individuell für Kunden gefertigt werden -> Handarbeit
B4: Pret-á-porter | C4: auch Ready to wear fashion -> in Serie produzierte Kleidung nach Maßgrößen
B5: Vertical Integration | C5: Erhöhung der Fertigungstiefe bzw. Verlängerung der Produktionskette
B6: Spring/Summer | C6: Haupt-Kollektion September/Oktober
B7: Autumn/ Winter | C7: Haupt-Kollektion Februar/März
B8: Pre-Fall | C8: Nebenkollektion Mai/Juni
B9: Resort/Cruise | C9: Nebenkollektion November/Dezember
B10: Big Four | C10: NY, London, Milan, Paris -> Fashion Weeks
B11: Défilés de mode | C11: Modeschau
B12: A-Linie | C12: Kleidungsstpck bildet die Form eines A
B13: androgyn | C13: Vereinigung von weiblichen und männlichen Elementen
B14: Atelier | C14: Werksatt eines Couturiers -> Modelle entworfen und handgefetigt
... B24: Maison | C24: Tradionreiches Modehaus
B26: Link

Sheet FX
B2: Currencies
B3: EUR/USD | C3: 1.04
B4: SEK M/USD | C4: 0.095
B5: YEN/USD | C5: 0.0063
B6: HKN Dollar/US Dollar | C6: 0.14
B7: Schweizer Franken/USD | C7: 1.12
B8: GBP/USD | C8: 1.24
B9: RMB/USD | C9: 0.14
B10: HKD/RMB | C10: 0.92
B11: PLN/USD | C11: 0.25
B12: INR/USD | C12: 0.011
B13: CAD/USD | C13: 0.69
B14: ZAR/USD | C14: 0.054
B15: TWD/USD | C15: 0.03

Sheet Acquisitions
A1: Main
B2: Name | C2: Parent/Owner | D2: Buyer | E2: Date | F2: Price | G2: Value | H2: Notes
B3: Versace | C3: Capri Holding | D3: Prada (1913.HK) | E3: 45757 | F3: n.a. | G3: 1250
B4: Skechers | C4: Skechers | D4: 3 G Capital | E4: 45782 | F4: 63$ | G4: 9420 | H4: https://investors.skechers.com/press-releases/detail/665/skechers-agrees-to-be-acquired-by-3g-capital
B5: About You | C5: About You | D5: Zalando SE | E5: 45637 | F5: n.a. | G5: 1100
B6: Hansebrand | C6: Hansebrand | D6: Gildan | E6: 45669 | F6: n.a. | G6: 2200 | H6: https://gildancorp.com/en/media/news/gildan-completes-acquisition-of-hanesbrands/
B7: Guess | C7: Guess | D7: Authentic Brands | E7: 45889 | F7: 16.75 | G7: 1.4 Billion USD | H7: https://investors.guess.com/news-releases/news-release-details/guess-co-founders-maurice-and-paul-marciano-and-ceo-carlos
B8: Farfetch | C8: FTCH | D8: Coupang | E8: 45322 | G8: 500 | H8: See Coupang Model for Farfetch numbers, buyed YOOX too
B9: Jack Wolfskin | C9: Topgolf Callaway Brands | D9: Anta Sports | E9: 45808 | G9: 290
B10: Allbirds | C10: Allbirds | D10: American Exchane Group | E10: 46112 | F10: n.a. | G10: 39
B11: Marc Jacob | C11: LVMH | D11: WHP Global: (joint venture with G-III Apparel Group) | E11: 46156 | F11: n.a. | G11: 850
B12: Everlane | C12: L Catterton | D12: SHEIN | E12: 46160 | F12: n.a. | G12: 100

Sheet People
A1: Main
B2: Name | C2: First | D2: Company | E2: Role | F2: Notes
B3: Arnault | C3: Bernhard | D3: LVMH | E3: LVMH CEO
B4: Williams | C4: Pharrell | D4: LVMH | E4: CD Louis Vuitton
B5: Gvasalia | C5: Demna | D5: Kering | E5: CD Gucci | F5: Former Creative Director of Balenciaga, Founder of Vetements
B6: Dumas | C6: Axel | D6: Hermes | E6: CEO of Hermes
B7: Ortega | C7: Amancio | D7: Inditex | E7: CEO of Inditex | F7: Founder of Inditex
B8: Prada | C8: Miuccia | D8: Prada | E8: Co-CEO Prada | F8: Designer
B9: Armani | C9: Girogio | D9: Armani | E9: Designer | F9: Founder of Armani
B10: Lauren | C10: Raloh | D10: Ralph Lauren | E10: Designer | F10: Founder of Ralph Lauren
B11: Pinault | C11: Franciose-Henri | D11: Kering | E11: Chairman | F11: Former CEO of Kering
B12: Yanai | C12: Tadashi | D12: Fast Retailing | E12: CEO | F12: Founder of Fast Retailing
B13: Versace | C13: Donatella | D13: Prada | E13: Creative Director at Versace
B14: Blazy | C14: Mattieu | D14: Chanel | E14: Creative Director
B15: Wintour | C15: Anna | D15: Vouge | E15: Chief Editor
B16: Neves | C16: Jose | D16: Coupon | E16: CEO Farfetch | F16: Founded Farfetch
B17: Ford | C17: Tom | D17: Tom Ford | E17: Creative Director
B20: Former influencial people
B21: Saint Laurent | C21: Yves | D21: Saint Laurent | E21: Designer
B22: Chanel | C22: Gabrielle "Coco" | D22: Coco Chanel
B23: McQueen | C23: Alexander | D23: McQueen | E23: Designer
B24: Balenciaga | C24: Cristobal | D24: Balenciaga | E24: Designer
B25: Dior | C25: Christian | D25: Dior | E25: Designer
B26: Lagerfeld | C26: Karl | D26: Lagerfeld | E26: Designer
B27: Westwood | C27: Vivienne | D27: Westwood | E27: Designer
B28: Versace | C28: Gianni | D28: Versace | E28: Designer
B29: Hermes | C29: Thierry

Sheet Industry
A1: Main
B2: Ressources
B3: https://www.mckinsey.com/industries/retail/our-insights/state-of-fashion
B4: https://www.businessoffashion.com/reports/the-state-of-fashion-industry/
B5: https://www.deloitte.com/global/en/Industries/consumer/perspectives/global-powers-of-luxury.html
B6: https://www.businessoffashion.com/user/newsletters/
B7: https://www.bain.com/insights/finding-a-new-longevity-for-luxury/
B8: https://dressedhistory.com/
B9: https://www.businessoffashion.com/podcasts/
B10: https://www.vogue.com/business
B11: https://monocle.com/newsletters/
B15: Books
B16: The luxury strategy
B17: Deluxe

Sheet Private
A1: Main
B3: Private
B4: SHEIN | C4: IPO on
B5: Hit Union | C5: n.a. | D5: JAP | E5: Brands: Fred Perry
B6: Chanel
B7: Rolex SA
B8: Primark
B9: Authentic Brands
B10: C&A
B11: Armani
B12: Audemar Piguet
B13: Patek Phillippe
B14: New Balance
B15: American Exchange Group | C15: Brands: Ed Hardy, Allbirds etc.
B16: Calzedonia
B17: Dolce & Gabbana
B18: Zellerfeld
B19: Marc'o Polo | C19: 630 Mio Rev in 2024 | E19: 150 stores
B21: Bankrupt
B22: Closed | C22: Marc'o Polo bought 75%
