Workbook

Sheet Main
A1: Industrials Universe
A2: numbers in mio USD

Sheet Automotive
A1: Automakers
A2: Numbers in mm USD
A3: # | B3: Name | C3: TICKR | D3: Country | E3: Price | F3: MC | G3: Net Debt | H3: EV | I3: Last Update | J3: Next Results | K3: Rev
A4: 1 | B4: Tesla | C4: TSLA | D4: US | E4: =+[2]Main!$K$2 -> 352.05 | F4: =+[2]Main!$K$4 -> 1139585.9 | G4: =+[2]Main!$K$6-[2]Main!$K$5 -> -34182 | H4: =+F4+G4 -> 1105403.9 | I4: Q424
A5: =A4+1 -> 2 | B5: Toyota | C5: TM | D5: JAP | E5: =+[4]Main!$J$2 -> 2420 | F5: =+[4]Main!$J$4*FX!C6 -> 260582.98 | G5: =+([4]Main!$J$6-[4]Main!$J$5)*FX!C6 -> 210150.34 | H5: =+F5+G5 -> 470733.32 | I5: FQ325
A6: =A5+1 -> 3 | B6: BYD | C6: 002594.SZ | D6: CHI | E6: =+[7]Main!$I$2 -> 372 | F6: =+[7]Main!$I$4*FX!C4 -> 151555.89 | G6: =+([7]Main!$I$6-[7]Main!$I$5)*FX!C4 -> 0 | H6: =+F6+G6 -> 151555.89 | I6: Q324
A7: =A6+1 -> 4 | B7: Ferrari | C7: RACE | D7: ITA | E7: =+[14]Main!$H$2 -> 296.4 | F7: =+[14]Main!$H$4*FX!C3 -> 57547.912 | G7: =+([14]Main!$H$6-[14]Main!$H$5)*FX!C3 -> 1458.8822 | H7: =+F7+G7 -> 59006.795 | I7: Q425
A8: =A7+1 -> 5 | B8: Mercedes Benz | C8: MBG.DE | D8: GER
A9: =A8+1 -> 6 | B9: Porsche | C9: P911.DE | D9: GER
A10: =A9+1 -> 7 | B10: BMW | C10: BMW.DE | D10: GER
A11: =A10+1 -> 8 | B11: Volkswagen | C11: VOW3.DE | D11: GER | E11: =+[15]Main!$J$2 -> 101.45 | F11: =+[15]Main!$J$4*FX!C3 -> 54880.578 | G11: =+([15]Main!$J$6-[15]Main!$J$5)*FX!C3 -> 226034.39 | H11: =+F11+G11 -> 280914.97 | I11: Q424
A12: =A11+1 -> 9 | B12: Stellanis | C12: STLA | D12: NE
A13: =A12+1 -> 10 | B13: General Motors | C13: GM | D13: US | E13: =+[16]Main!$I$2 -> 49.8 | F13: =+[16]Main!$I$4 -> 49551.094 | G13: =+[16]Main!$I$6-[16]Main!$I$5 -> 102595 | H13: =+F13+G13 -> 152146.09 | I13: Q424
A14: =A13+1 -> 11 | B14: Xiaomi | C14: XIACF | D14: CHI
A15: =A14+1 -> 12 | B15: Ford | C15: F | D15: US | E15: =+[17]Main!$I$2 -> 10.04 | F15: =+[17]Main!$I$4 -> 39910.807 | G15: =+[17]Main!$I$6-[17]Main!$I$5 -> 120174 | H15: =+F15+G15 -> 160084.81 | I15: Q424
A16: =A15+1 -> 13 | B16: Honda | C16: HMC | D16: JAP
A17: =A16+1 -> 14 | B17: Hyundai | C17: HYMFT | D17: KOR
A18: =A17+1 -> 15 | B18: Maruti Szuki | C18: MARUTI.NS | D18: IND
A19: =A18+1 -> 16 | B19: TATA Motors | C19: TATAMOTORS.NS | D19: IND
A20: =A19+1 -> 17 | B20: Mahindra & Mahindra | C20: M&M.NS | D20: IND
A21: =A20+1 -> 18 | B21: KIA | C21: 000270.SK | D21: KOR
A22: =A21+1 -> 19 | B22: Great Wall Motors | C22: 601633.SS | D22: CHI
A23: =A22+1 -> 20 | B23: Suzuki | C23: 7269.T | D23: JAP
A24: =A23+1 -> 21 | B24: Li Auto | C24: LI | D24: CHI
A25: =A24+1 -> 22 | B25: SAIC Motor | C25: 600104.SS | D25: CHI
A26: =A25+1 -> 23 | B26: Chongquing Chagan | C26: 000625.SZ | D26: CHI
A27: =A26+1 -> 24 | B27: Seres Group | C27: 601127.SZ | D27: CHI
... A53: =A52+1 -> 50 | B53: Polestar | C53: PSNY | D53: SWE
A54: =A53+1 -> 51 | B54: Aston Martin | C54: AML.L | D54: GB | E54: =+[18]Main!$I$2 -> 0.7415 | F54: =+[18]Main!$I$4*FX!C5 -> 796.21973 | G54: =+([18]Main!$I$6-[18]Main!$I$5)*FX!C5 -> 1324.443 | H54: =+F54+G54 -> 2120.6627 | I54: Q424
A55: =A54+1 -> 52 | B55: Force Motors | C55: FORCEMOT.NS | D55: IND
A56: =A55+1 -> 53 | B56: Nikolia | C56: NKLA | D56: US
A57: =A56+1 -> 54 | B57: NWTN | C57: NWTN | D57: UAE
A58: =A57+1 -> 55 | B58: Kandi Technolgies | C58: KNDI | D58: CHI
A59: =A58+1 -> 56 | B59: Canoo | C59: GOEV | D59: US
A60: =A59+1 -> 57 | B60: Cenntro Electric Group | C60: CENN | D60: US
A61: =A60+1 -> 58 | B61: REE Automotive | C61: REE | D61: ISRL
A62: =A61+1 -> 59 | B62: Mullen Automotive | C62: MULN | D62: US
A63: =A62+1 -> 60 | B63: Phoenix Motor | C63: PEV | D63: US
A64: =A63+1 -> 61 | B64: Fraraday Future | C64: FFIE | D64: US
A65: =A64+1 -> 62 | B65: Acrimoto | C65: FUV | D65: US
...

Sheet Manufacturing
A1: Main
A2: numbers in mio USD
A3: # | B3: Name | C3: Ticker | D3: Country | E3: Price | F3: MC | G3: Net Debt | H3: EV | I3: Updated | J3: Nxt Rslt
A4: 1 | B4: TSMC | C4: TSM | D4: TW | E4: =+[1]Main!$H$2 -> 2290 | F4: =+[1]Main!$H$4*FX!C7 -> 1840912.7 | G4: =+([1]Main!$H$6-[1]Main!$H$5)*FX!C7 -> -78602.546 | H4: =+F4+G4 -> 1762310.1 | I4: Q424
A5: =+A4+1 -> 2 | B5: Tesla | C5: TSLA | D5: US | E5: =+[2]Main!$K$2 -> 352.05 | F5: =+[2]Main!$K$4 -> 1139585.9 | G5: =+[2]Main!$K$6-[2]Main!$K$5 -> -34182 | H5: =+F5+G5 -> 1105403.9 | I5: Q424
A6: =+A5+1 -> 3 | B6: Samsung | C6: 005930.KS | D6: SK | E6: =+[3]Main!$J$2 -> 71500 | F6: =+[3]Main!$J$4*FX!C8 -> 294131.11 | G6: =+([3]Main!$J$6-[3]Main!$J$5)*FX!C8 -> -61521.654 | H6: =+F6+G6 -> 232609.46 | I6: Q424
A7: =+A6+1 -> 4 | B7: Toyota | C7: TM | D7: JAP | E7: =+[4]Main!$J$2 -> 2420 | F7: =+[4]Main!$J$4*FX!C6 -> 260582.98 | G7: =+([4]Main!$J$6-[4]Main!$J$5)*FX!C8 -> 22288.673 | H7: =+F7+G7 -> 282871.65 | I7: Q424
A8: =+A7+1 -> 5 | B8: Caterpillar | C8: CAT | D8: US | E8: =+[5]Main!$J$2 -> 298.69 | F8: =+[5]Main!$J$4 -> 142753.52 | G8: =+[5]Main!$J$6-[5]Main!$J$5 -> 31520 | H8: =+F8+G8 -> 174273.52 | I8: Q424
A9: =+A8+1 -> 6 | B9: Xiaomi | C9: 1810.HK | D9: CH | E9: =+[6]Main!$I$2 -> 56.2 | F9: =+[6]Main!$I$5*FX!C4 -> 187067.71 | G9: =+([6]Main!$I$7-[6]Main!$I$6)*FX!C4 -> -11416.861 | H9: =+F9+G9 -> 175650.84 | I9: Q125
A10: =+A9+1 -> 7 | B10: BYD | C10: 002594.SZ | D10: CH | E10: =+[7]Main!$I$2 -> 372 | F10: =+[7]Main!$I$4*FX!C4 -> 151555.89 | G10: =+([7]Main!$I$6-[7]Main!$I$5)*FX!C4 -> 0 | H10: =+F10+G10 -> 151555.89 | I10: Q424
A11: =+A10+1 -> 8 | B11: Airbus | C11: AIR.PA | D11: NE
A12: =+A11+1 -> 9 | B12: Deere & Company | C12: DE | D12: US | E12: =+[8]Main!$H$2 -> 485.5 | F12: =+[8]Main!$H$4 -> 131849.8 | G12: =+[8]Main!$H$6-[8]Main!$H$5 -> 56715 | H12: =+F12+G12 -> 188564.8 | I12: Q424
A13: =+A12+1 -> 10 | B13: Boeing | C13: BA | D13: US | E13: =+[9]Main!$I$2 -> 215.01 | F13: =+[9]Main!$I$4 -> 162118.72 | G13: =+[9]Main!$I$6-[9]Main!$I$5 -> 29944 | H13: =+F13+G13 -> 192062.72 | I13: Q125
A14: =+A13+1 -> 11 | B14: Lockheed Martin | C14: LMT | D14: US | E14: =+[10]Main!$K$2 -> 639 | F14: =+[10]Main!$K$4 -> 148695.3 | G14: =+[10]Main!$K$6-[10]Main!$K$5 -> 17579 | H14: =+F14+G14 -> 166274.3 | I14: Q224
A15: =+A14+1 -> 12 | B15: Analog Devices | C15: ADI | D15: US | E15: =+[11]Main!$J$2 -> 176.33 | F15: =+[11]Main!$J$4 -> 105088.53 | G15: =+[11]Main!$J$6-[11]Main!$J$5 -> 4296.957 | H15: =+F15+G15 -> 109385.49 | I15: Q125
A16: =+A15+1 -> 13 | B16: Intel | C16: INTC | D16: US | E16: =+[12]Main!$K$2 -> 82.72 | F16: =+[12]Main!$K$4 -> 85340 | G16: =+[12]Main!$K$6-[12]Main!$K$5 -> 12242 | H16: =+F16+G16 -> 97582 | I16: Q224
A17: =+A16+1 -> 14 | B17: Rolls Royce | C17: RL.L | D17: UK
A18: =+A17+1 -> 15 | B18: Amphenol | C18: US | D18: APH
A19: =+A18+1 -> 16 | B19: Midea | C19: 000333.SZ | D19: CH
A20: =+A19+1 -> 17 | B20: Ferrari | C20: RACE | D20: IT
A21: =+A20+1 -> 18 | B21: Atlas Copco | C21: ATCO.BST | D21: SWE
A22: =+A21+1 -> 19 | B22: Illinois Tools Work | C22: ITW | D22: US
A23: =+A22+1 -> 20 | B23: Foxconn | C23: 2317.TW | D23: TW
A24: =+A23+1 -> 21 | B24: Emerson | C24: EMR | D24: US
A25: =+A24+1 -> 22 | B25: Volvo Group | C25: Volvo.AST | D25: SWE
A26: =+A25+1 -> 23 | B26: Mercedes Benz | C26: MBG.DE | D26: GER
A27: =+A26+1 -> 24 | B27: Foxconn Industrial Internet | C27: 601138.SS | D27: CH
A28: =+A27+1 -> 25 | B28: Marvell Technology | C28: MRVL | D28: US
... A87: =+A86+1 -> 84 | B87: Rivian | C87: RIVN | D87: US
A88: =+A87+1 -> 85 | B88: Jabil | C88: JBL | D88: US | E88: =+[13]Main!$J$2 -> 134.8 | F88: =+[13]Main!$J$4 -> 14470.153 | G88: =+[13]Main!$J$6-[13]Main!$J$5 -> 1291 | H88: =+F88+G88 -> 15761.153 | I88: FQ225
A89: =+A88+1 -> 86 | B89: Renault | C89: RNO.PA | D89: FRA
A90: =+A89+1 -> 87 | B90: Masco | C90: MAS | D90: US
A91: =+A90+1 -> 88 | B91: Knorr-Bremse | C91: KBX.DE | D91: GER
A92: =+A91+1 -> 89 | B92: UPM.Kymmene | C92: UPM.HE | D92: FIN
A93: =+A92+1 -> 90 | B93: Avery Dennisom | C93: AVY | D93: US
A94: =+A93+1 -> 91 | B94: Kubota | C94: 6326.T | D94: JAP
A95: =+A94+1 -> 92 | B95: Unicharm | C95: 8113.T | D95: JAP
A96: =+A95+1 -> 93 | B96: First Solar | C96: FSLR | D96: US
A97: =+A96+1 -> 94 | B97: Textron | C97: TXT | D97: US
A98: =+A97+1 -> 95 | B98: Nitto Denko | C98: 6988.T | D98: JAP
...

Sheet Transportation
A1: Main
A2: numbers in mio USD
A3: # | B3: Name | C3: Ticker | D3: Country | E3: Price | F3: MC | G3: Net Debt | H3: EV | I3: Updated | J3: Next Rslts | L3: Notes
A4: 1 | B4: Uber | C4: UBER | D4: US | E4: =+[19]Main!$H$2 -> 75.69 | F4: =+[19]Main!$H$4 -> 155778.8 | G4: =+[19]Main!$H$6-[19]Main!$H$5 -> 2888 | H4: =+F4+G4 -> 158666.8 | I4: Q125
A5: =+A4+1 -> 2 | B5: Union Pacific Corporation | C5: UNP | D5: US | E5: =+[20]Main!$L$2 -> 221.76 | F5: =+[20]Main!$L$4 -> 131513.36 | G5: =+[20]Main!$L$6-[20]Main!$L$5 -> 31753 | H5: =+F5+G5 -> 163266.36 | I5: Q225
A6: =+A5+1 -> 3 | B6: United Parcel Service | C6: UPS | D6: US | E6: =+[21]Main!$J$2 -> 98.26 | F6: =+[21]Main!$J$4 -> 83206.352 | G6: =+[21]Main!$J$6-[21]Main!$J$5 -> 16304 | H6: =+F6+G6 -> 99510.352 | I6: Q125
A7: =+A6+1 -> 4 | B7: Canadian Pacific Railway | C7: CP | D7: CA | E7: =+[22]Main!$K$2 -> 114 | F7: =+[22]Main!$K$4*FX!C9 -> 76597.056 | G7: =+([22]Main!$K$6-[22]Main!$K$5)*FX!C9 -> 15809.04 | H7: =+F7+G7 -> 92406.096 | I7: Q125
A8: =+A7+1 -> 5 | B8: Canadian National Railway | C8: CNI | D8: CA | E8: =+[23]Main!$K$2 -> 150.99 | F8: =+[23]Main!$K$4*FX!C9 -> 68362.398 | G8: =+([23]Main!$K$6-[23]Main!$K$5)*FX!C9 -> 14754.96 | H8: =+F8+G8 -> 83117.358 | I8: Q424
A9: =+A8+1 -> 6 | B9: Kinder Morgan | C9: KMI | D9: US
A10: =+A9+1 -> 7 | B10: CSX Corporation | C10: CSX | D10: US
A11: =+A10+1 -> 8 | B11: FedEx | C11: FDX | D11: US
A12: =+A11+1 -> 9 | B12: TC Energy | C12: TRP | D12: CA
A13: =+A12+1 -> 10 | B13: DHL Group (Deutsche Post) | C13: DHL.DE | D13: GER
A14: =+A13+1 -> 11 | B14: DSV | C14: DSV.VI | D14: DE
A15: =+A14+1 -> 12 | B15: Old Dominion Freight Line | C15: ODFL | D15: US | E15: =+[24]Main!$J$2 -> 159.7 | F15: =+[24]Main!$J$4 -> 33748.665 | G15: =+[24]Main!$J$6-[24]Main!$J$5 -> -37.208 | H15: =+F15+G15 -> 33711.457 | I15: Q125
A16: =+A15+1 -> 13 | B16: COSCO Shipping | C16: 601919.SS | D16: CH
A17: =+A16+1 -> 14 | B17: Delta Air Lines | C17: DAL | D17: US | E17: =+[25]Main!$J$2 -> 41.41 | F17: =+[25]Main!$J$4 -> 27038.874 | G17: =+[25]Main!$J$6-[25]Main!$J$5 -> 12113 | H17: =+F17+G17 -> 39151.874 | I17: Q125
A18: =+A17+1 -> 15 | B18: Hapag-Lloyd | C18: HLAG.DE | D18: GER
A19: =+A18+1 -> 16 | B19: Kühne + Nagel | C19: KNIN.SW | D19: SW
A20: =+A19+1 -> 17 | B20: East Japan Railway | C20: 9020.T | D20: JAP | E20: =+[26]Main!$K$2 -> 3048 | F20: =+[26]Main!$K$4*FX!C6 -> 22758.353 | G20: =+([26]Main!$K$6-[26]Main!$K$5)*FX!C6 -> 28538.519 | H20: =+F20+G20 -> 51296.872 | I20: Q325
A21: =+A20+1 -> 18 | B21: Maersk | C21: MAERSK-B.CO | D21: DE
A22: =+A21+1 -> 19 | B22: InterGlobe Aviation | C22: INDIGO.NS | D22: IN
A23: =+A22+1 -> 20 | B23: Ryanair | C23: RYAAY | D23: IRE
A24: =+A23+1 -> 21 | B24: United Airlines Holdings | C24: UAL | D24: US
A25: =+A24+1 -> 22 | B25: Pembina Pipeline | C25: PBA | D25: CA
A26: =+A25+1 -> 23 | B26: Central Japan Railway | C26: 9022.T | D26: JAP
A27: =+A26+1 -> 24 | B27: Brambles | C27: BXB.AX | D27: AX
A28: =+A27+1 -> 25 | B28: DiDi | C28: DIDIY | D28: CH
A29: =+A28+1 -> 26 | B29: International Consolidated Airlines | C29: BABWF | D29: SING
A30: =+A29+1 -> 27 | B30: Air China | C30: 601111.SS | D30: CH
A31: =+A30+1 -> 28 | B31: Expeditors | C31: EXPD | D31: US | E31: =+[27]Main!$J$2 -> 114.99 | F31: =+[27]Main!$J$4 -> 15747.657 | G31: =+[27]Main!$J$6-[27]Main!$J$5 -> -1318.52 | H31: =+F31+G31 -> 14429.137 | I31: Q125
A32: =+A31+1 -> 29 | B32: Southwest Airlines | C32: LUV | D32: US
A33: =+A32+1 -> 30 | B33: Nippon Yūsen | C33: 9101.T | D33: JAP
A34: =+A33+1 -> 31 | B34: Singapore Airlines | C34: C6L.SI | D34: SING
A35: =+A34+1 -> 32 | B35: Evergreen Marine | C35: 2603.TW | D35: TW
A36: =+A35+1 -> 33 | B36: J. B. Hunt | C36: JBHT | D36: US
A37: =+A36+1 -> 34 | B37: China Southern Airlines | C37: 600029.SS | D37: CH
A38: =+A37+1 -> 35 | B38: Mitsui O.S.K. Lines | C38: 9104.T | D38: JAP
A39: =+A38+1 -> 36 | B39: HMM | C39: 011200.KS | D39: SK
A40: =+A39+1 -> 37 | B40: Plains All American Pipeline | C40: PAA | D40: US
...

Sheet Defense
A1: Main
A2: numbers in mio USD
A3: # | B3: Name | C3: Tickr | D3: Country | E3: Price | F3: MC | G3: Net Debt | H3: EV | I3: Update | J3: Notes
A4: 1 | B4: Boeing | C4: BA | D4: US | E4: =+[9]Main!$I$2 -> 215.01 | F4: =+[9]Main!$I$4 -> 162118.72 | G4: =+[9]Main!$I$6-[9]Main!$I$5 -> 29944 | H4: =+F4+G4 -> 192062.72 | I4: Q125
A5: =+A4+1 -> 2 | B5: Raytheon Technologies | C5: RTX | D5: US | E5: =+[29]Main!$H$3 -> 200.99 | F5: =+[29]Main!$H$5 -> 269786.4 | G5: =+[29]Main!$H$7-[29]Main!$H$6 -> 27057 | H5: =F5+G5 -> 296843.4 | I5: Q425
A6: =+A5+1 -> 3 | B6: Lockhead Martin | C6: LMT | D6: US | E6: =+[10]Main!$K$2 -> 639 | F6: =+[10]Main!$K$4 -> 148695.3 | G6: =+[10]Main!$K$6-[10]Main!$K$5 -> 17579 | H6: =F6+G6 -> 166274.3 | I6: Q425
A7: =+A6+1 -> 4 | B7: Honeywell | C7: HON | D7: US | E7: =+[30]Main!$K$3 -> 198.13 | F7: =+[30]Main!$K$5 -> 128719.35 | G7: =+[30]Main!$K$7-[30]Main!$K$6 -> 18125 | H7: =F7+G7 -> 146844.35 | I7: Q224
A8: =+A7+1 -> 5 | B8: Safran | C8: SAF.PA | D8: FRA
A9: =+A8+1 -> 6 | B9: General Dynamics | C9: GD | D9: US | E9: =+[31]Main!$H$2 -> 304.8 | F9: =+[31]Main!$H$4 -> 83752.206 | G9: =+[31]Main!$H$6-[31]Main!$H$5 -> 7899 | H9: =F9+G9 -> 91651.206 | I9: Q224
A10: =+A9+1 -> 7 | B10: Northgroup Norman | C10: NOC | D10: US | E10: =+[32]Main!$K$2 -> 519.93 | F10: =+[32]Main!$K$4 -> 76037.291 | G10: =+[32]Main!$K$6-[32]Main!$K$5 -> 11434 | H10: =F10+G10 -> 87471.291 | I10: Q224
A11: =+A10+1 -> 8 | B11: BAE Systemns | C11: BA.L | D11: UK
A12: =+A11+1 -> 9 | B12: L3Harris | C12: LHX | D12: US | E12: =+[33]Main!$I$3 -> 227.23 | F12: =+[33]Main!$I$5 -> 43106.71 | G12: =+[33]Main!$I$7-[33]Main!$I$6 -> 12705 | H12: =F12+G12 -> 55811.71 | I12: Q224
A13: =+A12+1 -> 10 | B13: Hindustan Aeronautics | C13: HAL.NS | D13: IND
A14: =+A13+1 -> 11 | B14: Axon Enterprise | C14: AXON | D14: US | E14: =+[34]Main!$K$2 -> 628.67 | F14: =+[34]Main!$K$4 -> 48170.749 | G14: =+[34]Main!$K$6-[34]Main!$K$5 -> -306.06 | H14: =F14+G14 -> 47864.689 | I14: Q424
A15: =+A14+1 -> 12 | B15: Thales | C15: HO.PA | D15: FRA
A16: =+A15+1 -> 13 | B16: Bharat Eletronics | C16: BEL.NS | D16: IND
A17: =+A16+1 -> 14 | B17: Rheinmetall | C17: RHM.F | D17: GER | E17: =+[35]Main!$I$2 -> 1332 | F17: =+[35]Main!$I$4*FX!C3 -> 62576.028 | G17: =+([35]Main!$I$6-[35]Main!$I$5)*FX!C3 -> 1350.51 | H17: =F17+G17 -> 63926.538 | I17: Q424
A18: =+A17+1 -> 15 | B18: Kongsberg Gruppen | C18: KOG.OL | D18: NOR
A19: =+A18+1 -> 16 | B19: Dassault Aviation | C19: AM.PA | D19: FRA
A20: =+A19+1 -> 17 | B20: Leonardo | C20: LDO.MI | D20: ITA
A21: =+A20+1 -> 18 | B21: SAAB AB | C21: SAAB.B-ST | D21: SWE
A22: =+A21+1 -> 19 | B22: Huntingtion Ingalls | C22: HII | D22: US | E22: =+[36]Main!$I$2 -> 265.21 | F22: =+[36]Main!$I$4 -> 10400.272 | G22: =+[36]Main!$I$6-[36]Main!$I$5 -> 2646 | H22: =F22+G22 -> 13046.272 | I22: Q224
A23: =+A22+1 -> 20 | B23: ELBIT Systems | C23: ESLT | D23: ISRL
A24: =+A23+1 -> 21 | B24: Leonardo DRS | C24: DRS | D24: US
A25: =+A24+1 -> 22 | B25: Aselsan | C25: ASELS.IS | D25: TUR
A26: =+A25+1 -> 23 | B26: Bharat Dynamics | C26: BDL.NS | D26: IND
A27: =+A26+1 -> 24 | B27: Aero Viroment | C27: AVAV | D27: US
A28: =+A27+1 -> 25 | B28: Hensfoldt | C28: HAG.F | D28: GER
A29: =+A28+1 -> 26 | B29: QinteiQ | C29: QQ.L | D29: UK
A30: =+A29+1 -> 27 | B30: Kratos DSS | C30: KTOS | D30: US
A31: =+A30+1 -> 28 | B31: Indra Sistemas | C31: IDR.MC | D31: SPA
A32: =+A31+1 -> 29 | B32: Mercury Systems | C32: MRCY | D32: US
A33: =+A32+1 -> 30 | B33: V2X | C33: VVX | D33: US
A34: =+A33+1 -> 31 | B34: VSE Corp | C34: VSEC | D34: US
... A40: =+A39+1 -> 37 | B40: Lubawa | C40: LBW.WA | D40: POL
A41: =+A40+1 -> 38 | B41: Voyager Technologies | C41: VOYG | D41: US | E41: =+[37]Main!$K$2 -> 52.3 | F41: =+[37]Main!$K$4 -> 2580.9004 | G41: =+[37]Main!$K$6-[37]Main!$K$5 -> -107.159 | H41: =+F41+G41 -> 2473.7414 | I41: Q125
A42: =+A41+1 -> 39 | B42: Smith & Wesson | C42: SWBI | D42: US | E42: =+[38]Main!$I$2 -> 8.28 | F42: =+[38]Main!$I$4 -> 367.14995 | G42: =+[38]Main!$I$6-[38]Main!$I$5 -> 72.964 | H42: =+F42+G42 -> 440.11395 | I42: Q126
A43: =+A42+1 -> 40 | B43: Firefly Aerospace | C43: FLY | D43: US
A44: =+A43+1 -> 41 | B44: Rocket Lab | C44: RKLB | D44: US
A45: =+A44+1 -> 42 | B45: Vincorion | D45: GER
...

Sheet Space
A1: Main
A2: numbers in mio USD
A3: # | B3: Name | C3: Ticker | D3: Country | E3: Price | F3: MC | G3: Net Debt | H3: EV | I3: Updated | J3: Next Rslts | L3: Notes
A4: 1 | B4: SpaceX | D4: US
A5: =+A4+1 -> 2 | B5: General Electric | C5: GE | D5: US
A6: =+A5+1 -> 3 | B6: RTX | C6: RTX | D6: US
A7: =+A6+1 -> 4 | B7: Boeing | C7: BA | D7: US
A8: =+A7+1 -> 5 | B8: Airbus | C8: AIR.PA | D8: NE
A9: =+A8+1 -> 6 | B9: Honeywell | C9: HON | D9: US
A10: =+A9+1 -> 7 | B10: Safran | C10: SAF.PA | D10: FRA
A11: =+A10+1 -> 8 | B11: Lockheed Martin | C11: LMT | D11: US
A12: =+A11+1 -> 9 | B12: Rolls-Royce Holdings | C12: RR.L | D12: UK
A13: =+A12+1 -> 10 | B13: Northrop Grumman | C13: NOC | D13: US
A14: =+A13+1 -> 11 | B14: Howmet Aerospace | C14: HWM | D14: US
A15: =+A14+1 -> 12 | B15: BAE Systems | C15: BA.L | D15: UK
A16: =+A15+1 -> 13 | B16: TransDigm Group | C16: TDG | D16: US
... A24: =+A23+1 -> 21 | B24: AST SpaceMobile | C24: ASTS | D24: ZS
A25: =+A24+1 -> 22 | B25: Hindustan Aeronautics | C25: HAL.NS
A26: =+A25+1 -> 23 | B26: China Satellite Communications | C26: 601698.SS
A27: =+A26+1 -> 24 | B27: Woodward | C27: WWD
A28: =+A27+1 -> 25 | B28: AVIC Shenyang Aircraft Company Limited | C28: 600760.SS
A29: =+A28+1 -> 26 | B29: MTU Aero Engines | C29: MTX.DE
A30: =+A29+1 -> 27 | B30: Hanwha Systems | C30: 272210.KS
A31: =+A30+1 -> 28 | B31: Bombardier | C31: BBD-B.TO
A32: =+A31+1 -> 29 | B32: Leonardo DRS | C32: DRS
A33: =+A32+1 -> 30 | B33: Embraer | C33: EMBJ
A34: =+A33+1 -> 31 | B34: Korea Aerospace Industries | C34: 047810.KS
A35: =+A34+1 -> 32 | B35: AeroVironment | C35: AVAV
A36: =+A35+1 -> 33 | B36: LIG Nex1 | C36: 079550.KS
... A80: =+A79+1 -> 77 | B80: Parrot S.A. | C80: PARRO.PA
A81: =+A80+1 -> 78
A82: =+A81+1 -> 79
A83: =+A82+1 -> 80
A84: =+A83+1 -> 81
A85: =+A84+1 -> 82
A86: =+A85+1 -> 83
A87: =+A86+1 -> 84
A88: =+A87+1 -> 85
A89: =+A88+1 -> 86
A90: =+A89+1 -> 87

Sheet Marine
A1: Main
A2: numbers in mio USD
A3: # | B3: Name | C3: Ticker | D3: Country | E3: Price | F3: MC | G3: Net Debt | H3: EV | I3: Updated | J3: Next Rslts | L3: Notes
A4: 1 | B4: Maersk | C4: MAERSK-B.CO | D4: Denmark
A5: =+A4+1 -> 2 | B5: COSCO Shipping | C5: 601919.SS | D5: China
A6: =+A5+1 -> 3 | B6: Hapag-Lloyd | C6: HLAG.DE | D6: Germany
A7: =+A6+1 -> 4 | B7: COSCO Shipping Energy | C7: 600026.SS | D7: China
A8: =+A7+1 -> 5 | B8: Nippon Yusen | C8: 9101.T | D8: Japan
A9: =+A8+1 -> 6 | B9: Evergreen Marine | C9: 2603.TW | D9: Taiwan
A10: =+A9+1 -> 7 | B10: Mitsui O.S.K. Lines | C10: 9104.T | D10: Japan
A11: =+A10+1 -> 8 | B11: HMM | C11: 011200.KS | D11: South Korea
A12: =+A11+1 -> 9 | B12: Orient Overseas Container Line | C12: 0316.HK | D12: Hong Kong
A13: =+A12+1 -> 10 | B13: SITC International | C13: 1308.HK | D13: Hong Kong
A14: =+A13+1 -> 11 | B14: Kawasaki Kisen Kaisha | C14: 9107.T | D14: Japan
A15: =+A14+1 -> 12 | B15: MISC Berhad | C15: 3816.KL | D15: Malaysia
A16: =+A15+1 -> 13 | B16: China Merchants Port | C16: 0144.HK | D16: Hong Kong
... A108: =+A107+1 -> 105 | B108: South Port NZ | C108: SPN.NZ | D108: New Zealand
A109: =+A108+1 -> 106
A110: =+A109+1 -> 107
A111: =+A110+1 -> 108
A112: =+A111+1 -> 109
A113: =+A112+1 -> 110
A114: =+A113+1 -> 111
A115: =+A114+1 -> 112
A116: =+A115+1 -> 113

Sheet Infrastructure
A1: Main
A2: numbers in mio USD
A3: # | B3: Name | C3: Ticker | D3: Country | E3: Price | F3: MC | G3: Net Debt | H3: EV | I3: Updated | J3: Nxt Rslt
A4: 1 | B4: GEO Group | C4: GEO | D4: United States | E4: =+[39]Main!$H$2 -> 21.5 | F4: =+[39]Main!$H$4 -> 3042.9942 | G4: =+[39]Main!$H$6-[39]Main!$H$5 -> 1628.315 | H4: =+F4+G4 -> 4671.3092 | I4: Q225
A5: =+A4+1 -> 2 | B5: Core Civic | C5: CXW | D5: United States | E5: =+[40]Main!$I$2 -> 20.58 | F5: =+[40]Main!$I$4 -> 2203.2937 | G5: =+[40]Main!$I$6-[40]Main!$I$5 -> 889.944 | H5: =+F5+G5 -> 3093.2377 | I5: Q225
A6: =+A5+1 -> 3 | B6: Union Pacific Corporation | C6: UNP | D6: United States
A7: =+A6+1 -> 4 | B7: American Tower | C7: AMT | D7: United States
A8: =+A7+1 -> 5 | B8: National Grid | C8: NGG | D8: United Kingdom
A9: =+A8+1 -> 6 | B9: Canadian Pacific Railway | C9: CP | D9: Canada
A10: =+A9+1 -> 7 | B10: Norfolk Southern | C10: NSC | D10: United States
A11: =+A10+1 -> 8 | B11: Kinder Morgan | C11: KMI | D11: United States
A12: =+A11+1 -> 9 | B12: CSX Corporation | C12: CSX | D12: United States
A13: =+A12+1 -> 10 | B13: TC Energy | C13: TRP | D13: Canada
A14: =+A13+1 -> 11 | B14: Sempra Energy | C14: SRE | D14: United States
A15: =+A14+1 -> 12 | B15: Aena | C15: AENA.MC | D15: Spain
A16: =+A15+1 -> 13 | B16: Crown Castle | C16: CCI | D16: United States
A17: =+A16+1 -> 14 | B17: Ferrovial | C17: FER.MC | D17: Spain
... A42: =+A41+1 -> 39 | B42: Grupo Aeroportuario del Sureste | C42: ASR | D42: Mexico
A43: =+A42+1 -> 40 | B43: Zurich Airport | C43: FHZN.SW | D43: Switzerland | E43: =+[41]Main!$J$2 -> 244.6 | F43: =+[41]Main!$J$4*FX!C10 -> 9687.4854 | G43: =+([41]Main!$J$6-[41]Main!$J$5)*FX!C10 -> 1729.116 | H43: =+F43+G43 -> 11416.601 | I43: Q425
A44: =+A43+1 -> 41 | B44: AltaGas | C44: ALA.TO | D44: Canada
A45: =+A44+1 -> 42 | B45: PetGas (Petronas Gas) | C45: 6033.KL | D45: Malaysia
A46: =+A45+1 -> 43 | B46: China Merchants Port | C46: 0144.HK | D46: Hong Kong
A47: =+A46+1 -> 44 | B47: Copenhagen Airport | C47: KBHL.CO | D47: Denmark
A48: =+A47+1 -> 45 | B48: Fraport | C48: FRA.DE | D48: Germany
A49: =+A48+1 -> 46 | B49: APA Group | C49: APA.AX | D49: Australia
A50: =+A49+1 -> 47 | B50: Auckland Airport | C50: AIA.AX | D50: New Zealand
A51: =+A50+1 -> 48 | B51: Keyera | C51: KEY.TO | D51: Canada
A52: =+A51+1 -> 49 | B52: Qingdao Port International | C52: 601298.SS | D52: China
A53: =+A52+1 -> 50 | B53: Infratil | C53: IFT.NZ | D53: New Zealand
A54: =+A53+1 -> 51 | B54: Construction Partners | C54: ROAD | D54: United States
A55: =+A54+1 -> 52 | B55: Shandong Hi-Speed | C55: 600350.SS | D55: China
... A133: =+A132+1 -> 130 | B133: Grupo Aeroportucario del Pacifico | C133: PAC | D133: Mexico
A134: =+A133+1 -> 131 | B134: Dangote Refinery | D134: Nigeria
A135: =+A134+1 -> 132

Sheet FX
A1: Main
B3: EUR/USD | C3: 1.09
B4: RMB/USD | C4: 0.14
B5: GBP/USD | C5: 1.29
B6: YEN/USD | C6: 0.0066
B7: TWD/USD | C7: 0.031
B8: WON/USD | C8: 0.0007
B9: CAD/USD | C9: 0.72
B10: CHF/USD | C10: 1.29
