Workbook

Sheet Dashbord

Sheet Portfolio
B2: Portfolio
B3: =TODAY() -> 45932
A5: x | B5: Assetklassen | C5: Name Wertpapier | D5: WKN | E5: Ticker | F5: Kurs | G5: Anteile | H5: Position | I5: Gewichtung (%) | M5: Allokation
C7: Core MSCI World USD (Acc) | D7: AORPWH | E7: #VALUE! | F7: {=_FV(E7,"Preis")} -> 108.465 | G7: 11.099527 | H7: =G7*F7 -> 1203.9102 | I7: =H7/H27 -> 0.44418545
C8: Core MSCI EM IMI USD (Acc) | D8: A111X9 | E8: #VALUE! | F8: {=_FV(E8,"Preis")} -> 37.442 | G8: 11.099527 | H8: =F8*G8 -> 415.58849 | I8: =H8/H27 -> 0.15333234
B9: ETFs | H9: =H7+H8 -> 1619.4987 | I9: =H9/H27 -> 0.59751779
C11: British American Tobaxxo | D11: 916018 | E11: #VALUE! | F11: {=_FV(E11,"Preis")} -> 44.15 | G11: 2 | H11: =F11*G11 -> 88.3
C12: Porsche Holding | D12: PAH003 | E12: #VALUE! | F12: {=_FV(E12,"Preis")} -> 34.21 | G12: 1 | H12: =F12*G12 -> 34.21 | I12: =H13/H27 -> 0.045200348
B13: Einzelaktien | H13: =SUM(H11:H12) -> 122.51 | I13: =H13/H27 -> 0.045200348
C15: Bitcoin | E15: #VALUE! | F15: {=_FV(E15,"Preis")} -> 102572.21 | G15: =0.00256356+0.00084895 -> 0.00341251 | H15: =G15*F15 -> 350.02869 | I15: =H15/H27 -> 0.1291439
C16: Ethereum | E16: #VALUE! | F16: {=_FV(E16,"Preis")} -> 3804.333 | G16: 0.03110663 | H16: =G16*F16 -> 118.33998
B17: Crypto | H17: =H15+H16 -> 468.36867 | I17: =H17/H27 -> 0.17280571
B20: Anleihen | H20: 0 | I20: =H20/H27 -> 0
B23: Cash | H23: 500 | I23: =H23/H27 -> 0.18447616
B27: Anlagevermögen | H27: =H23+H20+H17+H13+H9 -> 2710.3774 | I27: =I23+I20+I17+I13+I9 -> 1

Sheet Balance
A1: Dashboard
B3: ETFs
C4: Real | E4: Goal
B5: Name | C5: Value | D5: Allocation | E5: Value | F5: Allocation | G5: Deficit
B6: MSCI World | C6: 2269.09 | D6: =+C6/C8 -> 0.73149259 | E6: =+F6*E8 -> 2269.09 | F6: 0.7 | G6: =+E6-C6 -> 0
B7: MSCI EM | C7: 832.91 | D7: =+C7/C8 -> 0.26850741 | E7: =+E8*F7 -> 972.46714 | F7: 0.3 | G7: =+E7-C7 -> 139.55714
B8: Total | C8: =+SUM(C6:C7) -> 3102 | D8: =+D6+D7 -> 1 | E8: 3241.5571 | F8: =+F6+F7 -> 1 | G8: =+G6+G7 -> 139.55714
B10: Assets Class Allocation
C11: Real | E11: Goal
B12: Name | C12: Value | D12: Allocation | E12: Value | F12: Allocation | G12: Deficit
B13: ETFS | C13: 3099.04 | D13: =+C13/$C$17 -> 0.71787887 | E13: =+$E$17*F13 -> 3099.04 | F13: 0.7 | G13: =+E13-C13 -> 0
B14: Stocks | C14: 722.31 | D14: =+C14/$C$17 -> 0.16731991 | E14: =+$E$17*F14 -> 885.44 | F14: 0.2 | G14: =+E14-C14 -> 163.13
B15: Crypto | C15: 279.61 | D15: =+C15/$C$17 -> 0.064770416 | E15: =+$E$17*F15 -> 221.36 | F15: 0.05 | G15: =+E15-C15 -> -58.25
B16: Commodities | C16: 215.98 | D16: =+C16/$C$17 -> 0.050030809 | E16: =+$E$17*F16 -> 221.36 | F16: 0.05 | G16: =+E16-C16 -> 5.38
B17: Total | C17: =+SUM(C13:C16) -> 4316.94 | D17: =+SUM(D13:D16) -> 1 | E17: 4427.2 | F17: =+SUM(F13:F16) -> 1 | G17: =+SUM(G13:G16) -> 110.26

Sheet Trades
B2: # | C2: Typ | D2: Name | E2: Ticker | F2: Datum | G2: Anteile | H2: Buy-In | I2: Wert | J2: Notiz | K2: Kurs | L2: Haltedauer | M2: Status | N2: Dividende | O2: Costs | P2: Realized Gains
B3: 1 | C3: Kauf (Long) | D3: MSCI World | E3: #VALUE! | F3: 45070 | G3: 6.641006 | H3: 73.93 | I3: =G3*H3 -> 490.96957 | J3: Sparplan | K3: {=_FV(E3,"Schlusskurs des Vortags",TRUE)} -> 108.23 | L3: =YEARFRAC(F3,Portfolio!$B$3) -> 2.3555556 | M3: Offen | N3: 0 | O3: 1 | P3: 0
B4: =B3+1 -> 2 | C4: Kauf (Long) | D4: MSCI EM | E4: #VALUE! | F4: 45070 | G4: 7.715482 | H4: 27.35 | I4: =G4*H4 -> 211.01843 | J4: Sparplan | K4: {=_FV(E4,"Schlusskurs des Vortags",TRUE)} -> 37.159 | L4: =YEARFRAC(F4,Portfolio!$B$3) -> 2.3555556 | M4: Offen | N4: 0 | O4: 1 | P4: 0
B5: =B4+1 -> 3 | C5: Kauf (Long) | D5: Porsche Holding | E5: #VALUE! | F5: 45084 | G5: 1 | H5: 55.9 | I5: =G5*H5 -> 55.9 | J5: Value Play | K5: {=_FV(E5,"Schlusskurs des Vortags",TRUE)} -> 34 | L5: =YEARFRAC(F5,Portfolio!$B$3) -> 2.3194444 | M5: Offen | N5: 4.45 | O5: 1 | P5: 0
B6: =B5+1 -> 4 | C6: Kauf (Long) | D6: Bitcoin | E6: #VALUE! | F6: 45474 | G6: 0.00084805 | H6: 58958.79 | I6: =G6*H6 -> 50.000002 | J6: Langfristig Halten | K6: {=_FV(E6,"Schlusskurs des Vortags",TRUE)} -> 100252.32 | L6: =YEARFRAC(F6,Portfolio!$B$3) -> 1.2527778 | M6: Offen | N6: 0 | O6: 0 | P6: 0
B7: =B6+1 -> 5 | C7: Kauf (Long) | D7: Bitcoin | E7: #VALUE! | F7: 45475 | G7: 0.00256356 | H7: 58512.38 | I7: =H7*G7 -> 150 | J7: Langfristig Halten | K7: {=_FV(E7,"Schlusskurs des Vortags",TRUE)} -> 100252.32 | L7: =YEARFRAC(F7,Portfolio!$B$3) -> 1.25 | M7: Offen | N7: 0 | O7: 0 | P7: 0
B8: =B7+1 -> 6 | C8: Kauf (Long) | D8: Ethereum | E8: #VALUE! | F8: 45475 | G8: 0.03110663 | H8: 3214.75 | I8: =H8*G8 -> 100.00004 | J8: Langfristig Halten | K8: {=_FV(E8,"Schlusskurs des Vortags",TRUE)} -> 3695.712 | L8: =YEARFRAC(F8,Portfolio!$B$3) -> 1.25 | M8: Offen | N8: 0 | O8: 0 | P8: 0
B9: =B8+1 -> 7 | C9: Kauf (Long) | D9: MSCI World | E9: #VALUE! | F9: 45506 | G9: 1.544776 | H9: 90.628 | I9: =H9*G9 -> 139.99996 | J9: Sparplan | K9: {=_FV(E9,"Schlusskurs des Vortags",TRUE)} -> 108.23 | L9: =YEARFRAC(F9,Portfolio!$B$3) -> 1.1666667 | M9: Offen | N9: 0 | O9: 0 | P9: 0
B10: =B9+1 -> 8 | C10: Kauf (Long) | D10: MSCI EM | E10: #VALUE! | F10: 45506 | G10: 1.947546 | H10: 30.808 | I10: =H10*G10 -> 59.999997 | J10: Sparplan | K10: {=_FV(E10,"Schlusskurs des Vortags",TRUE)} -> 37.159 | L10: =YEARFRAC(F10,Portfolio!$B$3) -> 1.1666667 | M10: Offen | N10: 0 | O10: 0 | P10: 0
B11: =B10+1 -> 9 | C11: Kauf (Long) | D11: BAT | E11: #VALUE! | F11: 45509 | G11: 2 | H11: 31.83 | I11: =H11*G11 -> 63.66 | J11: Value Play | K11: {=_FV(E11,"Schlusskurs des Vortags",TRUE)} -> 45.05 | L11: =YEARFRAC(F11,Portfolio!$B$3) -> 1.1583333 | M11: Offen | N11: 0 | O11: 0.99 | P11: 0
B12: =B11+1 -> 10 | C12: Kauf (Long) | D12: MSCI World | E12: #VALUE! | F12: 45537 | G12: 1.465385 | H12: 95.538 | I12: =H12*G12 -> 139.99995 | J12: Sparplan | K12: {=_FV(E12,"Schlusskurs des Vortags",TRUE)} -> 108.23 | M12: Offen | N12: 0 | O12: 0 | P12: 0
B13: =B12+1 -> 11 | C13: Kauf (Long) | D13: MSCI EM | E13: #VALUE! | F13: 45537 | G13: 1.908457 | H13: 31.439 | I13: =H13*G13 -> 59.99998 | J13: Sparplan | K13: {=_FV(E13,"Schlusskurs des Vortags",TRUE)} -> 37.159 | M13: Offen | N13: 0 | O13: 0 | P13: 0
B14: =B13+1 -> 12 | C14: Kauf (Long) | D14: MSCI World | E14: #VALUE! | F14: 45567 | G14: 1.44836 | H14: 96.661 | I14: =H14*G14 -> 139.99993 | J14: Sparplan | K14: {=_FV(E14,"Schlusskurs des Vortags",TRUE)} -> 108.23 | M14: Offen | N14: 0 | O14: 0 | P14: 0
B15: =B14+1 -> 13 | C15: Kauf (Long) | D15: MSCI EM | E15: #VALUE! | F15: 45567 | G15: 1.778515 | H15: 33.736 | I15: =H15*G15 -> 59.999982 | J15: Sparplan | K15: {=_FV(E15,"Schlusskurs des Vortags",TRUE)} -> 37.159 | M15: Offen | N15: 0 | O15: 0 | P15: 0
B16: =B15+1 -> 14
B17: =B16+1 -> 15
B18: =B17+1 -> 16
B19: =B18+1 -> 17
B20: =B19+1 -> 18
B21: =B20+1 -> 19
B22: =B21+1 -> 20
B23: =B22+1 -> 21
B24: =B23+1 -> 22
B25: =B24+1 -> 23
B26: =B25+1 -> 24
B27: =B26+1 -> 25
B28: =B27+1 -> 26

Sheet Calculations
B1: numbers in Mio EUR
B3: General | J3: Daten | N3: Assetc Class Allocation | Q3: Value | R3: % | U3: Name | V3: % | W3: Value
B4: Total Cost | D4: =SUM(Trades!O3:O15) -> 3.99 | J4: Start Date | K4: 45070 | N4: ETFS | Q4: =Portfolio!H9 -> 1619.4987 | R4: =Q4/$Q$14 -> 0.73267973 | U4: ETFS | V4: =W4/SUM($W$4:$W$6) -> 0.73267973 | W4: =Q4 -> 1619.4987
B5: Total Dividends | D5: =SUM(Trades!N3:N15) -> 4.45 | J5: Duration | K5: =YEARFRAC(K4,Portfolio!B3) -> 2.3555556 | N5: MSCI World | Q5: =Portfolio!H7 -> 1203.9102 | R5: =Q5/$Q$4 -> 0.74338448 | U5: Stocks | V5: =W5/SUM($W$4:$W$6) -> 0.055424925 | W5: =Q7 -> 122.51
B6: Realized Gains | D6: =SUM(Trades!N3:N15)+SUM(Trades!P3:P15)-SUM(Trades!O3:O15) -> 0.46 | J6: Buy In | K6: =SUMPRODUCT(Trades!G3:G15,Trades!H3:H15) -> 1721.5478 | N6: MSCI EM | Q6: =Portfolio!H8 -> 415.58849 | R6: =Q6/$Q$4 -> 0.25661552 | U6: Crypto | V6: =W6/SUM($W$4:$W$6) -> 0.21189534 | W6: =Q10 -> 468.36867
B7: Unrealized Gains | D7: =K7-K6 -> 556.90959 | J7: Current Total | K7: =SUMPRODUCT(Trades!G3:G15,Trades!K3:K15) -> 2278.4574 | N7: Stocks | Q7: =Portfolio!H13 -> 122.51 | R7: =Q7/$Q$14 -> 0.055424925
N8: Porsche Holding | Q8: =Portfolio!H12 -> 34.21 | R8: =Q8/$Q$7 -> 0.27924251
J9: ROI | K9: =K7/K6-1 -> 0.32349353 | N9: BAT | Q9: =Portfolio!H11 -> 88.3 | R9: =Q9/$Q$7 -> 0.72075749
J10: Annualized Return | K10: =K9/K5 -> 0.13733216 | N10: Crypto | Q10: =Portfolio!H17 -> 468.36867 | R10: =Q10/$Q$14 -> 0.21189534
N11: Bitcoin | Q11: =Portfolio!H15 -> 350.02869 | R11: =Q11/$Q$10 -> 0.74733584
B12: Returns on Positions | J12: KPI'S | N12: Ethereum | Q12: =Portfolio!H16 -> 118.33998 | R12: =Q12/$Q$10 -> 0.25266416
B13: Name | D13: Type | E13: Nr. | F13: % | G13: Return | H13: A. Return | J13: Beta
B14: Msci Worl | D14: ETF | E14: 1 | F14: =(Trades!G3*Trades!K3)/$K$7 -> 0.31545732 | G14: =Trades!K3/Trades!H3-1 -> 0.46395239 | H14: =Calculations!G14/Trades!L3 -> 0.19696092 | J14: Sharpe Ratio | N14: Total | Q14: =Q4+Q7+Q10 -> 2210.3774 | R14: =Q14/$Q$14 -> 1
B15: MSCI EM | D15: ETF | E15: =E14+1 -> 2 | F15: =(Trades!G4*Trades!K4)/$K$7 -> 0.12583057 | G15: =Trades!K4/Trades!H4-1 -> 0.35864717 | H15: =Calculations!G15/Trades!L4 -> 0.15225587 | J15: Jensen Alpha
B16: Porsche Holding | D16: Stock | E16: =E15+1 -> 3 | F16: =(Trades!G5*Trades!K5)/$K$7 -> 0.014922377 | G16: =Trades!K5/Trades!H5-1 -> -0.39177102 | H16: =Calculations!G16/Trades!L5 -> -0.16890727 | J16: Treynor Ratio
B17: Bitcoin | D17: Crypto | E17: =E16+1 -> 4 | F17: =(Trades!G6*Trades!K6)/$K$7 -> 0.037314273 | G17: =Trades!K6/Trades!H6-1 -> 0.70037959 | H17: =Calculations!G17/Trades!L6 -> 0.55906131 | J17: Information Ratio | N17: Assetc Class Allocation | T17: Index
B18: Bitcoin | D18: Crypto | E18: =E17+1 -> 5 | F18: =(Trades!G7*Trades!K7)/$K$7 -> 0.11279686 | G18: =Trades!K7/Trades!H7-1 -> 0.71335234 | H18: =Calculations!G18/Trades!L7 -> 0.57068187 | N18: Vereinigte Staaten | O18: =S18*$R$48 -> 0.49593665 | S18: 0.7176 | T18: MSCI World
B19: Ethereum | D19: Crypto | E19: =E18+1 -> 6 | F19: =(Trades!G8*Trades!K8)/$K$7 -> 0.050455692 | G19: =Trades!K8/Trades!H8-1 -> 0.14961101 | H19: =Calculations!G19/Trades!L8 -> 0.11968881 | J19: Annual Returns | N19: Japan | O19: =S19*$R$48 -> 0.039462072 | S19: 0.0571 | T19: MSCI World
B20: BAT | D20: Stock | E20: =E19+1 -> 7 | F20: =(Trades!G9*Trades!K9)/$K$7 -> 0.073379078 | G20: =Trades!K9/Trades!H9-1 -> 0.19422254 | H20: =Calculations!G20/Trades!L9 -> 0.16647646 | J20: Return 2023 | K20: =(Prices!C10-55.9)/Prices!C3-1 -> 0.022705764 | N20: Vereinigtes Königreich | O20: =S20*$R$48 -> 0.025709091 | S20: 0.0372 | T20: MSCI World
N21: Kanada | O21: =S21*$R$48 -> 0.020456696 | S21: 0.0296 | T21: MSCI World
N22: Frankreich | O22: =S22*$R$48 -> 0.01962737 | S22: 0.0284 | T22: MSCI World
N23: Schweiz | O23: =S23*$R$48 -> 0.016932062 | S23: 0.0245 | T23: MSCI World
N24: Deutschland | O24: =S24*$R$48+R50 -> 0.034566108 | S24: 0.0216 | T24: MSCI World
N25: Australien | O25: =S25*$R$48 -> 0.012854545 | S25: 0.0186 | T25: MSCI World
N26: Niederlande | O26: =S26*$R$48 -> 0.0088461387 | S26: 0.0128 | T26: MSCI World
N27: China | O27: =S27*$R$49 -> 0.059236571 | S27: 0.2483 | T27: MSCI EM
N28: Indien | O28: =S28*$R$49 -> 0.046019874 | S28: 0.1929 | T28: MSCI EM
N29: Taiwan | O29: =S29*$R$49 -> 0.043634188 | S29: 0.1829 | T29: MSCI EM
N30: Korea | O30: =S30*$R$49 -> 0.028270373 | S30: 0.1185 | T30: MSCI EM
N31: Saudi-Arabien | O31: =S31*$R$49 -> 0.0073001977 | S31: 0.0306 | T31: MSCI EM
N32: Südafrika | O32: =S32*$R$49 -> 0.059236571 | S32: 0.2483 | T32: MSCI EM
N33: Brasilien | O33: =S33*$R$49 -> 0.046019874 | S33: 0.1929 | T33: MSCI EM
N34: Mexiko | O34: =S34*$R$49 -> 0.043634188 | S34: 0.1829 | T34: MSCI EM
N35: Deutschland | O35: =S35*$R$49 -> 0.028270373 | S35: 0.1185 | T35: MSCI EM
N36: Indonesien | O36: =S36*$R$49 -> 0.015840952 | S36: 0.0664 | T36: MSCI EM
N37: Malaysia | O37: =S37*$R$49 -> 0.0073001977 | S37: 0.0306 | T37: MSCI EM
N38: Thailand | O38: =S38*$R$49 -> 0.0070377723 | S38: 0.0295 | T38: MSCI EM
N39: Ver. Arabische Emirate | O39: =S39*$R$49 -> 0.0062982098 | S39: 0.0264 | T39: MSCI EM
S40: 0.0223 | T40: MSCI EM
N41: Cash und/oder Derivate | O41: =S40*R49 -> 0.0053200787 | S41: 0.0035 | T41: MSCI World
...

Sheet Prices
B1: Portfolio | D1: 45070 | G1: EUNL | I1: 45070 | K1: IS3N | M1: 45070 | O1: BTC/EUR | Q1: 45474 | S1: ETH/EUR | U1: 45475 | W1: PAH3 | Y1: 45114
B2: Date | C2: Value | D2: Buy In | E2: Volatilität | G2: Close | H2: Shares | I2: Position | K2: Close | L2: Shares | M2: Position | O2: Close | P2: Shares | Q2: Position | S2: Close | T2: Shares | U2: Position | W2: Close | X2: Shares | Y2: Position
A3: x | B3: 45070 | C3: =I3+M3+Q3+U3+Y3 -> 702.79042 | D3: 701.98801 | G3: 73.93 | H3: 6.641006 | I3: =H3*G3 -> 490.96957 | K3: 27.454 | L3: 7.715482 | M3: =K3*L3 -> 211.82084
B4: 45075 | C4: =I4+M4+Q4+U4+Y4 -> 723.12803 | D4: 701.98801 | E4: =(C4-(D4-D3))/C3-1 -> 0.028938373 | G4: 76.3 | H4: 6.641006 | I4: =H4*G4 -> 506.70876 | K4: 28.05 | L4: 7.715482 | M4: =K4*L4 -> 216.41927
B5: 45082 | C5: =I5+M5+Q5+U5+Y5 -> 726.78076 | D5: 701.98801 | E5: =(C5-(D5-D4))/C4-1 -> 0.0050513003 | G5: 76.34 | H5: 6.641006 | I5: =H5*G5 -> 506.9744 | K5: 28.489 | L5: 7.715482 | M5: =K5*L5 -> 219.80637
B6: 45089 | C6: =I6+M6+Q6+U6+Y6 -> 732.36139 | D6: 701.98801 | E6: =(C6-(D6-D5))/C5-1 -> 0.0076785475 | G6: 77.02 | H6: 6.641006 | I6: =H6*G6 -> 511.49028 | K6: 28.627 | L6: 7.715482 | M6: =K6*L6 -> 220.8711
B7: 45096 | C7: =I7+M7+Q7+U7+Y7 -> 715.36266 | D7: 701.98801 | E7: =(C7-(D7-D6))/C6-1 -> -0.023210847 | G7: 75.614 | H7: 6.641006 | I7: =H7*G7 -> 502.15303 | K7: 27.634 | L7: 7.715482 | M7: =K7*L7 -> 213.20963
B8: 45103 | C8: =I8+M8+Q8+U8+Y8 -> 729.62164 | D8: 701.98801 | E8: =(C8-(D8-D7))/C7-1 -> 0.019932518 | G8: 77.43 | H8: 6.641006 | I8: =H8*G8 -> 514.21309 | K8: 27.919 | L8: 7.715482 | M8: =K8*L8 -> 215.40854
B9: 45110 | C9: =I9+M9+Q9+U9+Y9 -> 716.84328 | D9: 701.98801 | E9: =(C9-(D9-D8))/C8-1 -> -0.017513679 | G9: 76.024 | H9: 6.641006 | I9: =H9*G9 -> 504.87584 | K9: 27.473 | L9: 7.715482 | M9: =K9*L9 -> 211.96744
A10: x | B10: 45114 | C10: =I10+M10+Q10+U10+Y10 -> 774.64781 | D10: 757.88801 | E10: =(C10-(D10-D9))/C9-1 -> 0.0026568325 | G10: 76.14 | H10: 6.641006 | I10: =H10*G10 -> 505.6462 | K10: 27.62 | L10: 7.715482 | M10: =K10*L10 -> 213.10161 | W10: 55.9 | X10: 1 | Y10: =W10*X10 -> 55.9
B11: 45117 | C11: =I11+M11+Q11+U11+Y11 -> 775.70878 | D11: 757.88801 | E11: =(C11-(D11-D10))/C10-1 -> 0.0013696219 | G11: 76.334 | H11: 6.641006 | I11: =H11*G11 -> 506.93455 | K11: 27.899 | L11: 7.715482 | M11: =K11*L11 -> 215.25423 | W11: 53.52 | X11: 1 | Y11: =W11*X11 -> 53.52
B12: 45124 | C12: =I12+M12+Q12+U12+Y12 -> 785.04016 | D12: 757.88801 | E12: =(C12-(D12-D11))/C11-1 -> 0.012029488 | G12: 77.68 | H12: 6.641006 | I12: =H12*G12 -> 515.87335 | K12: 27.911 | L12: 7.715482 | M12: =K12*L12 -> 215.34682 | W12: 53.82 | X12: 1 | Y12: =W12*X12 -> 53.82
B13: 45131 | C13: =I13+M13+Q13+U13+Y13 -> 802.04503 | D13: 757.88801 | E13: =(C13-(D13-D12))/C12-1 -> 0.021661138 | G13: 78.938 | H13: 6.641006 | I13: =H13*G13 -> 524.22773 | K13: 29.027 | L13: 7.715482 | M13: =K13*L13 -> 223.9573 | W13: 53.86 | X13: 1 | Y13: =W13*X13 -> 53.86
B14: 45138 | C14: =I14+M14+Q14+U14+Y14 -> 783.07555 | D14: 757.88801 | E14: =(C14-(D14-D13))/C13-1 -> -0.023651386 | G14: 77.068 | H14: 6.641006 | I14: =H14*G14 -> 511.80905 | K14: 28.362 | L14: 7.715482 | M14: =K14*L14 -> 218.8265 | W14: 52.44 | X14: 1 | Y14: =W14*X14 -> 52.44
B15: 45145 | C15: =I15+M15+Q15+U15+Y15 -> 776.71216 | D15: 757.88801 | E15: =(C15-(D15-D14))/C14-1 -> -0.0081261566 | G15: 77.162 | H15: 6.641006 | I15: =H15*G15 -> 512.4333 | K15: 27.7 | L15: 7.715482 | M15: =K15*L15 -> 213.71885 | W15: 50.56 | X15: 1 | Y15: =W15*X15 -> 50.56
B16: 45152 | C16: =I16+M16+Q16+U16+Y16 -> 762.52838 | D16: 757.88801 | E16: =(C16-(D16-D15))/C15-1 -> -0.018261304 | G16: 75.802 | H16: 6.641006 | I16: =H16*G16 -> 503.40154 | K16: 27.215 | L16: 7.715482 | M16: =K16*L16 -> 209.97684 | W16: 49.15 | X16: 1 | Y16: =W16*X16 -> 49.15
B17: 45159 | C17: =I17+M17+Q17+U17+Y17 -> 773.96765 | D17: 757.88801 | E17: =(C17-(D17-D16))/C16-1 -> 0.01500176 | G17: 76.944 | H17: 6.641006 | I17: =H17*G17 -> 510.98557 | K17: 27.773 | L17: 7.715482 | M17: =K17*L17 -> 214.28208 | W17: 48.7 | X17: 1 | Y17: =W17*X17 -> 48.7
B18: 45166 | C18: =I18+M18+Q18+U18+Y18 -> 791.41743 | D18: 757.88801 | E18: =(C18-(D18-D17))/C17-1 -> 0.022545884 | G18: 79.052 | H18: 6.641006 | I18: =H18*G18 -> 524.98481 | K18: 28.228 | L18: 7.715482 | M18: =K18*L18 -> 217.79263 | W18: 48.64 | X18: 1 | Y18: =W18*X18 -> 48.64
B19: 45173 | C19: =I19+M19+Q19+U19+Y19 -> 786.19051 | D19: 757.88801 | E19: =(C19-(D19-D18))/C18-1 -> -0.0066045022 | G19: 78.566 | H19: 6.641006 | I19: =H19*G19 -> 521.75728 | K19: 28.022 | L19: 7.715482 | M19: =K19*L19 -> 216.20324 | W19: 48.23 | X19: 1 | Y19: =W19*X19 -> 48.23
B20: 45180 | C20: =I20+M20+Q20+U20+Y20 -> 792.37373 | D20: 757.88801 | E20: =(C20-(D20-D19))/C19-1 -> 0.0078647746 | G20: 79.122 | H20: 6.641006 | I20: =H20*G20 -> 525.44968 | K20: 28.223 | L20: 7.715482 | M20: =K20*L20 -> 217.75405 | W20: 49.17 | X20: 1 | Y20: =W20*X20 -> 49.17
B21: 45187 | C21: =I21+M21+Q21+U21+Y21 -> 775.17056 | D21: 757.88801 | E21: =(C21-(D21-D20))/C20-1 -> -0.021710926 | G21: 77.022 | H21: 6.641006 | I21: =H21*G21 -> 511.50356 | K21: 27.819 | L21: 7.715482 | M21: =K21*L21 -> 214.63699 | W21: 49.03 | X21: 1 | Y21: =W21*X21 -> 49.03
B22: 45194 | C22: =I22+M22+Q22+U22+Y22 -> 772.26191 | D22: 757.88801 | E22: =(C22-(D22-D21))/C21-1 -> -0.0037522638 | G22: 76.972 | H22: 6.641006 | I22: =H22*G22 -> 511.17151 | K22: 27.8 | L22: 7.715482 | M22: =K22*L22 -> 214.4904 | W22: 46.6 | X22: 1 | Y22: =W22*X22 -> 46.6
... B61: 45467 | C61: =I61+M61+Q61+U61+Y61 -> 918.67816 | D61: 757.88801 | E61: =(C61-(D61-D60))/C60-1 -> 0.00066060253 | G61: 94.82 | H61: 6.641006 | I61: =H61*G61 -> 629.70019 | K61: 31.977 | L61: 7.715482 | M61: =K61*L61 -> 246.71797 | W61: 42.26 | X61: 1 | Y61: =W61*X61 -> 42.26
A62: x | B62: 45474 | C62: =I62+M62+Q62+U62+Y62 -> 974.79833 | D62: 807.88801 | E62: =(C62-(D62-D61))/C61-1 -> 0.0066619328 | G62: 95.452 | H62: 6.641006 | I62: =H62*G62 -> 633.8973 | K62: 32.142 | L62: 7.715482 | M62: =K62*L62 -> 247.99102 | O62: 58958.79 | P62: 0.00084805 | Q62: =P62*O62 -> 50.000002 | W62: 42.91 | X62: 1 | Y62: =W62*X62 -> 42.91
A63: x | B63: 45475 | C63: =I63+M63+Q63+U63+Y63 -> 1217.3562 | D63: 957.88801 | E63: =(C63-(D63-D62))/C62-1 -> 0.094950749 | G63: 94.83 | H63: 6.641006 | I63: =H63*G63 -> 629.7666 | K63: 31.85 | L63: 7.715482 | M63: =K63*L63 -> 245.7381 | O63: 58512.38 | P63: 0.00341161 | Q63: =P63*O63 -> 199.62142 | S63: 3214.75 | T63: 0.03110663 | U63: =S63*T63 -> 100.00004 | W63: 42.23 | X63: 1 | Y63: =W63*X63 -> 42.23
B64: 45481 | C64: =I64+M64+Q64+U64+Y64 -> 1205.0085 | D64: 957.88801 | E64: =(C64-(D64-D63))/C63-1 -> -0.010142983 | G64: 96.538 | H64: 6.641006 | I64: =H64*G64 -> 641.10944 | K64: 32.656 | L64: 7.715482 | M64: =K64*L64 -> 251.95678 | O64: 52744.523 | P64: 0.00341161 | Q64: =P64*O64 -> 179.94374 | S64: 2850.472 | T64: 0.03110663 | U64: =S64*T64 -> 88.668578 | W64: 43.33 | X64: 1 | Y64: =W64*X64 -> 43.33
B65: 45488 | C65: =I65+M65+Q65+U65+Y65 -> 1221.9668 | D65: 957.88801 | E65: =(C65-(D65-D64))/C64-1 -> 0.014073116 | G65: 94.364 | H65: 6.641006 | I65: =H65*G65 -> 626.67189 | K65: 31.429 | L65: 7.715482 | M65: =K65*L65 -> 242.48988 | O65: 61557.761 | P65: 0.00341161 | Q65: =P65*O65 -> 210.01107 | S65: 3222.59 | T65: 0.03110663 | U65: =S65*T65 -> 100.24391 | W65: 42.55 | X65: 1 | Y65: =W65*X65 -> 42.55
B66: 45495 | C66: =I66+M66+Q66+U66+Y66 -> 1212.3275 | D66: 957.88801 | E66: =(C66-(D66-D65))/C65-1 -> -0.0078883004 | G66: 93.946 | H66: 6.641006 | I66: =H66*G66 -> 623.89595 | K66: 31.309 | L66: 7.715482 | M66: =K66*L66 -> 241.56403 | O66: 62104.052 | P66: 0.00341161 | Q66: =P66*O66 -> 211.8748 | S66: 2996.234 | T66: 0.03110663 | U66: =S66*T66 -> 93.202742 | W66: 41.79 | X66: 1 | Y66: =W66*X66 -> 41.79
B67: 45502 | C67: =I67+M67+Q67+U67+Y67 -> 1163.7437 | D67: 957.88801 | E67: =(C67-(D67-D66))/C66-1 -> -0.040074836 | G67: 91.092 | H67: 6.641006 | I67: =H67*G67 -> 604.94252 | K67: 30.545 | L67: 7.715482 | M67: =K67*L67 -> 235.6694 | O67: 57312.133 | P67: 0.00341161 | Q67: =P67*O67 -> 195.52665 | S67: 2763.563 | T67: 0.03110663 | U67: =S67*T67 -> 85.965132 | W67: 41.64 | X67: 1 | Y67: =W67*X67 -> 41.64
B68: 45506 | C68: =I68+M68+Q68+U68+Y68 -> 1361.3414 | D68: 1157.888 | E68: =(C68-(D68-D67))/C67-1 -> -0.0020642475 | G68: 90.628 | H68: 8.185782 | I68: =H68*G68 -> 741.86105 | K68: 30.808 | L68: 9.663028 | M68: =K68*L68 -> 297.69857 | O68: 57312.133 | P68: 0.00341161 | Q68: =P68*O68 -> 195.52665 | S68: 2763.563 | T68: 0.03110663 | U68: =S68*T68 -> 85.965132 | W68: 40.29 | X68: 1 | Y68: =W68*X68 -> 40.29
